{
 "cells": [
  {
   "cell_type": "code",
   "execution_count": 1,
   "id": "e179637a",
   "metadata": {},
   "outputs": [],
   "source": [
    "import numpy as np\n",
    "import pandas as pd\n",
    "import matplotlib.pyplot as plt\n",
    "%matplotlib inline\n",
    "\n",
    "from os.path import join\n",
    "\n",
    "import tensorflow as tf \n",
    "from tensorflow.keras import layers, models, optimizers\n",
    "from tensorflow.keras.utils import to_categorical"
   ]
  },
  {
   "cell_type": "code",
   "execution_count": 2,
   "id": "c7ca85c3",
   "metadata": {},
   "outputs": [],
   "source": [
    "datax = np.load(join('data', 'MNIST.npy'))\n",
    "datay = np.load(join('data', 'Label.npy'))"
   ]
  },
  {
   "cell_type": "code",
   "execution_count": 3,
   "id": "bf8b5d99",
   "metadata": {},
   "outputs": [
    {
     "name": "stdout",
     "output_type": "stream",
     "text": [
      "최대 : 1.0, 최소 : 0.0\n"
     ]
    }
   ],
   "source": [
    "datax_norm = datax/255\n",
    "print('최대 : {}, 최소 : {}'.format(np.max(datax_norm), np.min(datax_norm)))"
   ]
  },
  {
   "cell_type": "code",
   "execution_count": 4,
   "id": "9b0b2afe",
   "metadata": {},
   "outputs": [],
   "source": [
    "datay_onehot = to_categorical(datay)"
   ]
  },
  {
   "cell_type": "code",
   "execution_count": 5,
   "id": "52a9faea",
   "metadata": {},
   "outputs": [],
   "source": [
    "from sklearn.model_selection import train_test_split\n",
    "trnx, tstx, trny, tsty = train_test_split(datax_norm, datay_onehot, test_size = 0.3, random_state = 111)"
   ]
  },
  {
   "cell_type": "code",
   "execution_count": 9,
   "id": "13d7701f",
   "metadata": {},
   "outputs": [
    {
     "name": "stdout",
     "output_type": "stream",
     "text": [
      "(42000, 28, 28)\n",
      "(42000, 10)\n",
      "ERROR! Session/line number was not unique in database. History logging moved to new session 114\n"
     ]
    }
   ],
   "source": [
    "print(trnx.shape)\n",
    "print(trny.shape)"
   ]
  },
  {
   "cell_type": "code",
   "execution_count": 6,
   "id": "e2cbb797",
   "metadata": {},
   "outputs": [
    {
     "name": "stderr",
     "output_type": "stream",
     "text": [
      "2022-05-04 12:25:46.050228: I tensorflow/stream_executor/platform/default/dso_loader.cc:44] Successfully opened dynamic library libcuda.so.1\n",
      "2022-05-04 12:25:46.141706: I tensorflow/stream_executor/cuda/cuda_gpu_executor.cc:981] successful NUMA node read from SysFS had negative value (-1), but there must be at least one NUMA node, so returning NUMA node zero\n",
      "2022-05-04 12:25:46.141922: I tensorflow/core/common_runtime/gpu/gpu_device.cc:1555] Found device 0 with properties: \n",
      "pciBusID: 0000:01:00.0 name: NVIDIA GeForce RTX 3050 computeCapability: 8.6\n",
      "coreClock: 1.845GHz coreCount: 20 deviceMemorySize: 7.79GiB deviceMemoryBandwidth: 208.65GiB/s\n",
      "2022-05-04 12:25:46.144671: I tensorflow/stream_executor/platform/default/dso_loader.cc:44] Successfully opened dynamic library libcudart.so.10.1\n",
      "2022-05-04 12:25:46.192215: I tensorflow/stream_executor/platform/default/dso_loader.cc:44] Successfully opened dynamic library libcublas.so.10\n",
      "2022-05-04 12:25:46.219297: I tensorflow/stream_executor/platform/default/dso_loader.cc:44] Successfully opened dynamic library libcufft.so.10\n",
      "2022-05-04 12:25:46.226286: I tensorflow/stream_executor/platform/default/dso_loader.cc:44] Successfully opened dynamic library libcurand.so.10\n",
      "2022-05-04 12:25:46.277142: I tensorflow/stream_executor/platform/default/dso_loader.cc:44] Successfully opened dynamic library libcusolver.so.10\n",
      "2022-05-04 12:25:46.285712: I tensorflow/stream_executor/platform/default/dso_loader.cc:44] Successfully opened dynamic library libcusparse.so.10\n",
      "2022-05-04 12:25:46.376890: I tensorflow/stream_executor/platform/default/dso_loader.cc:44] Successfully opened dynamic library libcudnn.so.7\n",
      "2022-05-04 12:25:46.377208: I tensorflow/stream_executor/cuda/cuda_gpu_executor.cc:981] successful NUMA node read from SysFS had negative value (-1), but there must be at least one NUMA node, so returning NUMA node zero\n",
      "2022-05-04 12:25:46.377321: I tensorflow/stream_executor/cuda/cuda_gpu_executor.cc:981] successful NUMA node read from SysFS had negative value (-1), but there must be at least one NUMA node, so returning NUMA node zero\n",
      "2022-05-04 12:25:46.377356: I tensorflow/core/common_runtime/gpu/gpu_device.cc:1697] Adding visible gpu devices: 0\n",
      "2022-05-04 12:25:46.377654: I tensorflow/core/platform/cpu_feature_guard.cc:142] Your CPU supports instructions that this TensorFlow binary was not compiled to use: SSE4.1 SSE4.2 AVX AVX2 FMA\n",
      "2022-05-04 12:25:46.422294: I tensorflow/core/platform/profile_utils/cpu_utils.cc:94] CPU Frequency: 3686400000 Hz\n",
      "2022-05-04 12:25:46.425115: I tensorflow/compiler/xla/service/service.cc:168] XLA service 0x55f84546a360 initialized for platform Host (this does not guarantee that XLA will be used). Devices:\n",
      "2022-05-04 12:25:46.425203: I tensorflow/compiler/xla/service/service.cc:176]   StreamExecutor device (0): Host, Default Version\n",
      "2022-05-04 12:25:46.516249: I tensorflow/stream_executor/cuda/cuda_gpu_executor.cc:981] successful NUMA node read from SysFS had negative value (-1), but there must be at least one NUMA node, so returning NUMA node zero\n",
      "2022-05-04 12:25:46.516353: I tensorflow/compiler/xla/service/service.cc:168] XLA service 0x55f8454414a0 initialized for platform CUDA (this does not guarantee that XLA will be used). Devices:\n",
      "2022-05-04 12:25:46.516361: I tensorflow/compiler/xla/service/service.cc:176]   StreamExecutor device (0): NVIDIA GeForce RTX 3050, Compute Capability 8.6\n",
      "2022-05-04 12:25:46.516475: I tensorflow/stream_executor/cuda/cuda_gpu_executor.cc:981] successful NUMA node read from SysFS had negative value (-1), but there must be at least one NUMA node, so returning NUMA node zero\n",
      "2022-05-04 12:25:46.516759: I tensorflow/core/common_runtime/gpu/gpu_device.cc:1555] Found device 0 with properties: \n",
      "pciBusID: 0000:01:00.0 name: NVIDIA GeForce RTX 3050 computeCapability: 8.6\n",
      "coreClock: 1.845GHz coreCount: 20 deviceMemorySize: 7.79GiB deviceMemoryBandwidth: 208.65GiB/s\n",
      "2022-05-04 12:25:46.516794: I tensorflow/stream_executor/platform/default/dso_loader.cc:44] Successfully opened dynamic library libcudart.so.10.1\n",
      "2022-05-04 12:25:46.516803: I tensorflow/stream_executor/platform/default/dso_loader.cc:44] Successfully opened dynamic library libcublas.so.10\n",
      "2022-05-04 12:25:46.516809: I tensorflow/stream_executor/platform/default/dso_loader.cc:44] Successfully opened dynamic library libcufft.so.10\n",
      "2022-05-04 12:25:46.516817: I tensorflow/stream_executor/platform/default/dso_loader.cc:44] Successfully opened dynamic library libcurand.so.10\n",
      "2022-05-04 12:25:46.516823: I tensorflow/stream_executor/platform/default/dso_loader.cc:44] Successfully opened dynamic library libcusolver.so.10\n",
      "2022-05-04 12:25:46.516829: I tensorflow/stream_executor/platform/default/dso_loader.cc:44] Successfully opened dynamic library libcusparse.so.10\n",
      "2022-05-04 12:25:46.516836: I tensorflow/stream_executor/platform/default/dso_loader.cc:44] Successfully opened dynamic library libcudnn.so.7\n",
      "2022-05-04 12:25:46.516909: I tensorflow/stream_executor/cuda/cuda_gpu_executor.cc:981] successful NUMA node read from SysFS had negative value (-1), but there must be at least one NUMA node, so returning NUMA node zero\n",
      "2022-05-04 12:25:46.516977: I tensorflow/stream_executor/cuda/cuda_gpu_executor.cc:981] successful NUMA node read from SysFS had negative value (-1), but there must be at least one NUMA node, so returning NUMA node zero\n",
      "2022-05-04 12:25:46.517010: I tensorflow/core/common_runtime/gpu/gpu_device.cc:1697] Adding visible gpu devices: 0\n",
      "2022-05-04 12:25:46.517602: I tensorflow/stream_executor/platform/default/dso_loader.cc:44] Successfully opened dynamic library libcudart.so.10.1\n",
      "2022-05-04 12:25:46.518026: I tensorflow/core/common_runtime/gpu/gpu_device.cc:1096] Device interconnect StreamExecutor with strength 1 edge matrix:\n",
      "2022-05-04 12:25:46.518030: I tensorflow/core/common_runtime/gpu/gpu_device.cc:1102]      0 \n",
      "2022-05-04 12:25:46.518034: I tensorflow/core/common_runtime/gpu/gpu_device.cc:1115] 0:   N \n",
      "2022-05-04 12:25:46.518077: I tensorflow/stream_executor/cuda/cuda_gpu_executor.cc:981] successful NUMA node read from SysFS had negative value (-1), but there must be at least one NUMA node, so returning NUMA node zero\n",
      "2022-05-04 12:25:46.518243: I tensorflow/stream_executor/cuda/cuda_gpu_executor.cc:981] successful NUMA node read from SysFS had negative value (-1), but there must be at least one NUMA node, so returning NUMA node zero\n",
      "2022-05-04 12:25:46.518308: I tensorflow/core/common_runtime/gpu/gpu_device.cc:1241] Created TensorFlow device (/job:localhost/replica:0/task:0/device:GPU:0 with 7074 MB memory) -> physical GPU (device: 0, name: NVIDIA GeForce RTX 3050, pci bus id: 0000:01:00.0, compute capability: 8.6)\n"
     ]
    }
   ],
   "source": [
    "input_shape = (28, 28, 1)\n",
    "\n",
    "input_tensor = layers.Input(shape = input_shape)\n",
    "\n",
    "conv1_1 = layers.Conv2D(16, (2,2), padding = 'same')(input_tensor)\n",
    "conv1_2 = layers.BatchNormalization()(conv1_1)\n",
    "conv1_3 = layers.Activation(\"relu\")(conv1_2)\n",
    "conv1_4 = layers.MaxPooling2D((2,2))(conv1_3)\n",
    "\n",
    "conv2_1 = layers.Conv2D(32, (2,2), padding = 'same')(conv1_4)\n",
    "conv2_2 = layers.BatchNormalization()(conv2_1)\n",
    "conv2_3 = layers.Activation(\"relu\")(conv2_2)\n",
    "conv2_4 = layers.Dropout(0.2)(conv2_3)\n",
    "\n",
    "flatted = layers.Flatten()(conv2_4)\n",
    "\n",
    "dense1 = layers.Dense(64, activation = 'relu')(flatted)\n",
    "dense2 = layers.Dense(32, activation = 'relu')(dense1)\n",
    "output_class = layers.Dense(5, activation = \"softmax\")(dense2)\n",
    "\n",
    "cnn_fmodel = models.Model(input_tensor, output_class)\n",
    "cnn_fmodel.compile(optimizer='Adam', loss = 'categorical_crossentropy', metrics=['accuracy'])"
   ]
  },
  {
   "cell_type": "code",
   "execution_count": 7,
   "id": "92e4474d",
   "metadata": {},
   "outputs": [
    {
     "name": "stdout",
     "output_type": "stream",
     "text": [
      "Model: \"model\"\n",
      "_________________________________________________________________\n",
      "Layer (type)                 Output Shape              Param #   \n",
      "=================================================================\n",
      "input_1 (InputLayer)         [(None, 28, 28, 1)]       0         \n",
      "_________________________________________________________________\n",
      "conv2d (Conv2D)              (None, 28, 28, 16)        80        \n",
      "_________________________________________________________________\n",
      "batch_normalization (BatchNo (None, 28, 28, 16)        64        \n",
      "_________________________________________________________________\n",
      "activation (Activation)      (None, 28, 28, 16)        0         \n",
      "_________________________________________________________________\n",
      "max_pooling2d (MaxPooling2D) (None, 14, 14, 16)        0         \n",
      "_________________________________________________________________\n",
      "conv2d_1 (Conv2D)            (None, 14, 14, 32)        2080      \n",
      "_________________________________________________________________\n",
      "batch_normalization_1 (Batch (None, 14, 14, 32)        128       \n",
      "_________________________________________________________________\n",
      "activation_1 (Activation)    (None, 14, 14, 32)        0         \n",
      "_________________________________________________________________\n",
      "dropout (Dropout)            (None, 14, 14, 32)        0         \n",
      "_________________________________________________________________\n",
      "flatten (Flatten)            (None, 6272)              0         \n",
      "_________________________________________________________________\n",
      "dense (Dense)                (None, 64)                401472    \n",
      "_________________________________________________________________\n",
      "dense_1 (Dense)              (None, 32)                2080      \n",
      "_________________________________________________________________\n",
      "dense_2 (Dense)              (None, 5)                 165       \n",
      "=================================================================\n",
      "Total params: 406,069\n",
      "Trainable params: 405,973\n",
      "Non-trainable params: 96\n",
      "_________________________________________________________________\n"
     ]
    }
   ],
   "source": [
    "cnn_fmodel.summary()"
   ]
  },
  {
   "cell_type": "code",
   "execution_count": 15,
   "id": "7e8f5905",
   "metadata": {},
   "outputs": [
    {
     "data": {
      "text/plain": [
       "(42000, 28, 28, 1)"
      ]
     },
     "execution_count": 15,
     "metadata": {},
     "output_type": "execute_result"
    }
   ],
   "source": [
    "trnx_reshape = trnx.reshape(-1,28,28,1)\n",
    "tstx_reshape = tstx.reshape(-1,28,28,1)\n",
    "trnx_reshape.shape"
   ]
  },
  {
   "cell_type": "code",
   "execution_count": null,
   "id": "f61fef14",
   "metadata": {},
   "outputs": [
    {
     "name": "stderr",
     "output_type": "stream",
     "text": [
      "ERROR:root:Internal Python error in the inspect module.\n",
      "Below is the traceback from this internal error.\n",
      "\n",
      "ERROR:root:Internal Python error in the inspect module.\n",
      "Below is the traceback from this internal error.\n",
      "\n",
      "ERROR:root:Internal Python error in the inspect module.\n",
      "Below is the traceback from this internal error.\n",
      "\n"
     ]
    },
    {
     "name": "stdout",
     "output_type": "stream",
     "text": [
      "Traceback (most recent call last):\n",
      "  File \"/home/questionnote/miniconda3/envs/tensorflow/lib/python3.7/site-packages/IPython/core/interactiveshell.py\", line 3524, in run_code\n",
      "    exec(code_obj, self.user_global_ns, self.user_ns)\n",
      "  File \"/tmp/ipykernel_3447/2078233165.py\", line 1, in <module>\n",
      "    history = cnn_fmodel.fit(trnx_reshape, trny, validation_data = [tstx_reshape, tsty], batch_size = 10, epochs = 10)\n",
      "  File \"/home/questionnote/miniconda3/envs/tensorflow/lib/python3.7/site-packages/tensorflow_core/python/keras/engine/training.py\", line 819, in fit\n",
      "    use_multiprocessing=use_multiprocessing)\n",
      "  File \"/home/questionnote/miniconda3/envs/tensorflow/lib/python3.7/site-packages/tensorflow_core/python/keras/engine/training_v2.py\", line 235, in fit\n",
      "    use_multiprocessing=use_multiprocessing)\n",
      "  File \"/home/questionnote/miniconda3/envs/tensorflow/lib/python3.7/site-packages/tensorflow_core/python/keras/engine/training_v2.py\", line 593, in _process_training_inputs\n",
      "    use_multiprocessing=use_multiprocessing)\n",
      "  File \"/home/questionnote/miniconda3/envs/tensorflow/lib/python3.7/site-packages/tensorflow_core/python/keras/engine/training_v2.py\", line 646, in _process_inputs\n",
      "    x, y, sample_weight=sample_weights)\n",
      "  File \"/home/questionnote/miniconda3/envs/tensorflow/lib/python3.7/site-packages/tensorflow_core/python/keras/engine/training.py\", line 2383, in _standardize_user_data\n",
      "    batch_size=batch_size)\n",
      "  File \"/home/questionnote/miniconda3/envs/tensorflow/lib/python3.7/site-packages/tensorflow_core/python/keras/engine/training.py\", line 2489, in _standardize_tensors\n",
      "    y, self._feed_loss_fns, feed_output_shapes)\n",
      "  File \"/home/questionnote/miniconda3/envs/tensorflow/lib/python3.7/site-packages/tensorflow_core/python/keras/engine/training_utils.py\", line 810, in check_loss_and_target_compatibility\n",
      "    ' while using as loss `' + loss_name + '`. '\n",
      "ValueError: A target array with shape (42000, 10) was passed for an output of shape (None, 5) while using as loss `categorical_crossentropy`. This loss expects targets to have the same shape as the output.\n",
      "\n",
      "During handling of the above exception, another exception occurred:\n",
      "\n",
      "Traceback (most recent call last):\n",
      "  File \"/home/questionnote/miniconda3/envs/tensorflow/lib/python3.7/site-packages/IPython/core/interactiveshell.py\", line 2088, in showtraceback\n",
      "    stb = value._render_traceback_()\n",
      "AttributeError: 'ValueError' object has no attribute '_render_traceback_'\n",
      "\n",
      "During handling of the above exception, another exception occurred:\n",
      "\n",
      "Traceback (most recent call last):\n",
      "  File \"/home/questionnote/miniconda3/envs/tensorflow/lib/python3.7/site-packages/IPython/core/ultratb.py\", line 1101, in get_records\n",
      "    return _fixed_getinnerframes(etb, number_of_lines_of_context, tb_offset)\n",
      "  File \"/home/questionnote/miniconda3/envs/tensorflow/lib/python3.7/site-packages/IPython/core/ultratb.py\", line 248, in wrapped\n",
      "    return f(*args, **kwargs)\n",
      "  File \"/home/questionnote/miniconda3/envs/tensorflow/lib/python3.7/site-packages/IPython/core/ultratb.py\", line 281, in _fixed_getinnerframes\n",
      "    records = fix_frame_records_filenames(inspect.getinnerframes(etb, context))\n",
      "  File \"/home/questionnote/miniconda3/envs/tensorflow/lib/python3.7/inspect.py\", line 1502, in getinnerframes\n",
      "    frameinfo = (tb.tb_frame,) + getframeinfo(tb, context)\n",
      "  File \"/home/questionnote/miniconda3/envs/tensorflow/lib/python3.7/inspect.py\", line 1460, in getframeinfo\n",
      "    filename = getsourcefile(frame) or getfile(frame)\n",
      "  File \"/home/questionnote/miniconda3/envs/tensorflow/lib/python3.7/inspect.py\", line 696, in getsourcefile\n",
      "    if getattr(getmodule(object, filename), '__loader__', None) is not None:\n",
      "  File \"/home/questionnote/miniconda3/envs/tensorflow/lib/python3.7/inspect.py\", line 733, in getmodule\n",
      "    if ismodule(module) and hasattr(module, '__file__'):\n",
      "  File \"/home/questionnote/miniconda3/envs/tensorflow/lib/python3.7/site-packages/tensorflow/__init__.py\", line 50, in __getattr__\n",
      "    module = self._load()\n",
      "  File \"/home/questionnote/miniconda3/envs/tensorflow/lib/python3.7/site-packages/tensorflow/__init__.py\", line 44, in _load\n",
      "    module = _importlib.import_module(self.__name__)\n",
      "  File \"/home/questionnote/miniconda3/envs/tensorflow/lib/python3.7/importlib/__init__.py\", line 127, in import_module\n",
      "    return _bootstrap._gcd_import(name[level:], package, level)\n",
      "  File \"<frozen importlib._bootstrap>\", line 1006, in _gcd_import\n",
      "  File \"<frozen importlib._bootstrap>\", line 983, in _find_and_load\n",
      "  File \"<frozen importlib._bootstrap>\", line 965, in _find_and_load_unlocked\n",
      "ModuleNotFoundError: No module named 'tensorflow_core.estimator'\n",
      "Traceback (most recent call last):\n",
      "  File \"/home/questionnote/miniconda3/envs/tensorflow/lib/python3.7/site-packages/IPython/core/interactiveshell.py\", line 3524, in run_code\n",
      "    exec(code_obj, self.user_global_ns, self.user_ns)\n",
      "  File \"/tmp/ipykernel_3447/2078233165.py\", line 1, in <module>\n",
      "    history = cnn_fmodel.fit(trnx_reshape, trny, validation_data = [tstx_reshape, tsty], batch_size = 10, epochs = 10)\n",
      "  File \"/home/questionnote/miniconda3/envs/tensorflow/lib/python3.7/site-packages/tensorflow_core/python/keras/engine/training.py\", line 819, in fit\n",
      "    use_multiprocessing=use_multiprocessing)\n",
      "  File \"/home/questionnote/miniconda3/envs/tensorflow/lib/python3.7/site-packages/tensorflow_core/python/keras/engine/training_v2.py\", line 235, in fit\n",
      "    use_multiprocessing=use_multiprocessing)\n",
      "  File \"/home/questionnote/miniconda3/envs/tensorflow/lib/python3.7/site-packages/tensorflow_core/python/keras/engine/training_v2.py\", line 593, in _process_training_inputs\n",
      "    use_multiprocessing=use_multiprocessing)\n",
      "  File \"/home/questionnote/miniconda3/envs/tensorflow/lib/python3.7/site-packages/tensorflow_core/python/keras/engine/training_v2.py\", line 646, in _process_inputs\n",
      "    x, y, sample_weight=sample_weights)\n",
      "  File \"/home/questionnote/miniconda3/envs/tensorflow/lib/python3.7/site-packages/tensorflow_core/python/keras/engine/training.py\", line 2383, in _standardize_user_data\n",
      "    batch_size=batch_size)\n",
      "  File \"/home/questionnote/miniconda3/envs/tensorflow/lib/python3.7/site-packages/tensorflow_core/python/keras/engine/training.py\", line 2489, in _standardize_tensors\n",
      "    y, self._feed_loss_fns, feed_output_shapes)\n",
      "  File \"/home/questionnote/miniconda3/envs/tensorflow/lib/python3.7/site-packages/tensorflow_core/python/keras/engine/training_utils.py\", line 810, in check_loss_and_target_compatibility\n",
      "    ' while using as loss `' + loss_name + '`. '\n",
      "ValueError: A target array with shape (42000, 10) was passed for an output of shape (None, 5) while using as loss `categorical_crossentropy`. This loss expects targets to have the same shape as the output.\n",
      "\n",
      "During handling of the above exception, another exception occurred:\n",
      "\n",
      "Traceback (most recent call last):\n",
      "  File \"/home/questionnote/miniconda3/envs/tensorflow/lib/python3.7/site-packages/IPython/core/interactiveshell.py\", line 2088, in showtraceback\n",
      "    stb = value._render_traceback_()\n",
      "AttributeError: 'ValueError' object has no attribute '_render_traceback_'\n",
      "\n",
      "During handling of the above exception, another exception occurred:\n",
      "\n",
      "Traceback (most recent call last):\n",
      "  File \"/home/questionnote/miniconda3/envs/tensorflow/lib/python3.7/site-packages/IPython/core/interactiveshell.py\", line 3444, in run_ast_nodes\n",
      "    if (await self.run_code(code, result,  async_=asy)):\n",
      "  File \"/home/questionnote/miniconda3/envs/tensorflow/lib/python3.7/site-packages/IPython/core/interactiveshell.py\", line 3541, in run_code\n",
      "    self.showtraceback(running_compiled_code=True)\n",
      "  File \"/home/questionnote/miniconda3/envs/tensorflow/lib/python3.7/site-packages/IPython/core/interactiveshell.py\", line 2091, in showtraceback\n",
      "    value, tb, tb_offset=tb_offset)\n",
      "  File \"/home/questionnote/miniconda3/envs/tensorflow/lib/python3.7/site-packages/IPython/core/ultratb.py\", line 1368, in structured_traceback\n",
      "    self, etype, value, tb, tb_offset, number_of_lines_of_context)\n",
      "  File \"/home/questionnote/miniconda3/envs/tensorflow/lib/python3.7/site-packages/IPython/core/ultratb.py\", line 1268, in structured_traceback\n",
      "    self, etype, value, tb, tb_offset, number_of_lines_of_context\n",
      "  File \"/home/questionnote/miniconda3/envs/tensorflow/lib/python3.7/site-packages/IPython/core/ultratb.py\", line 1125, in structured_traceback\n",
      "    tb_offset)\n",
      "  File \"/home/questionnote/miniconda3/envs/tensorflow/lib/python3.7/site-packages/IPython/core/ultratb.py\", line 1082, in format_exception_as_a_whole\n",
      "    last_unique, recursion_repeat = find_recursion(orig_etype, evalue, records)\n",
      "  File \"/home/questionnote/miniconda3/envs/tensorflow/lib/python3.7/site-packages/IPython/core/ultratb.py\", line 382, in find_recursion\n",
      "    return len(records), 0\n",
      "TypeError: object of type 'NoneType' has no len()\n",
      "\n",
      "During handling of the above exception, another exception occurred:\n",
      "\n",
      "Traceback (most recent call last):\n",
      "  File \"/home/questionnote/miniconda3/envs/tensorflow/lib/python3.7/site-packages/IPython/core/interactiveshell.py\", line 2088, in showtraceback\n",
      "    stb = value._render_traceback_()\n",
      "AttributeError: 'TypeError' object has no attribute '_render_traceback_'\n",
      "\n",
      "During handling of the above exception, another exception occurred:\n",
      "\n",
      "Traceback (most recent call last):\n",
      "  File \"/home/questionnote/miniconda3/envs/tensorflow/lib/python3.7/site-packages/IPython/core/ultratb.py\", line 1101, in get_records\n",
      "    return _fixed_getinnerframes(etb, number_of_lines_of_context, tb_offset)\n",
      "  File \"/home/questionnote/miniconda3/envs/tensorflow/lib/python3.7/site-packages/IPython/core/ultratb.py\", line 248, in wrapped\n",
      "    return f(*args, **kwargs)\n",
      "  File \"/home/questionnote/miniconda3/envs/tensorflow/lib/python3.7/site-packages/IPython/core/ultratb.py\", line 281, in _fixed_getinnerframes\n",
      "    records = fix_frame_records_filenames(inspect.getinnerframes(etb, context))\n",
      "  File \"/home/questionnote/miniconda3/envs/tensorflow/lib/python3.7/inspect.py\", line 1502, in getinnerframes\n",
      "    frameinfo = (tb.tb_frame,) + getframeinfo(tb, context)\n",
      "  File \"/home/questionnote/miniconda3/envs/tensorflow/lib/python3.7/inspect.py\", line 1460, in getframeinfo\n",
      "    filename = getsourcefile(frame) or getfile(frame)\n",
      "  File \"/home/questionnote/miniconda3/envs/tensorflow/lib/python3.7/inspect.py\", line 696, in getsourcefile\n",
      "    if getattr(getmodule(object, filename), '__loader__', None) is not None:\n",
      "  File \"/home/questionnote/miniconda3/envs/tensorflow/lib/python3.7/inspect.py\", line 733, in getmodule\n",
      "    if ismodule(module) and hasattr(module, '__file__'):\n",
      "  File \"/home/questionnote/miniconda3/envs/tensorflow/lib/python3.7/site-packages/tensorflow/__init__.py\", line 50, in __getattr__\n",
      "    module = self._load()\n",
      "  File \"/home/questionnote/miniconda3/envs/tensorflow/lib/python3.7/site-packages/tensorflow/__init__.py\", line 44, in _load\n",
      "    module = _importlib.import_module(self.__name__)\n",
      "  File \"/home/questionnote/miniconda3/envs/tensorflow/lib/python3.7/importlib/__init__.py\", line 127, in import_module\n",
      "    return _bootstrap._gcd_import(name[level:], package, level)\n",
      "  File \"<frozen importlib._bootstrap>\", line 1006, in _gcd_import\n",
      "  File \"<frozen importlib._bootstrap>\", line 983, in _find_and_load\n",
      "  File \"<frozen importlib._bootstrap>\", line 965, in _find_and_load_unlocked\n",
      "ModuleNotFoundError: No module named 'tensorflow_core.estimator'\n",
      "Traceback (most recent call last):\n",
      "  File \"/home/questionnote/miniconda3/envs/tensorflow/lib/python3.7/site-packages/IPython/core/interactiveshell.py\", line 3524, in run_code\n",
      "    exec(code_obj, self.user_global_ns, self.user_ns)\n",
      "  File \"/tmp/ipykernel_3447/2078233165.py\", line 1, in <module>\n",
      "    history = cnn_fmodel.fit(trnx_reshape, trny, validation_data = [tstx_reshape, tsty], batch_size = 10, epochs = 10)\n",
      "  File \"/home/questionnote/miniconda3/envs/tensorflow/lib/python3.7/site-packages/tensorflow_core/python/keras/engine/training.py\", line 819, in fit\n",
      "    use_multiprocessing=use_multiprocessing)\n",
      "  File \"/home/questionnote/miniconda3/envs/tensorflow/lib/python3.7/site-packages/tensorflow_core/python/keras/engine/training_v2.py\", line 235, in fit\n",
      "    use_multiprocessing=use_multiprocessing)\n",
      "  File \"/home/questionnote/miniconda3/envs/tensorflow/lib/python3.7/site-packages/tensorflow_core/python/keras/engine/training_v2.py\", line 593, in _process_training_inputs\n",
      "    use_multiprocessing=use_multiprocessing)\n",
      "  File \"/home/questionnote/miniconda3/envs/tensorflow/lib/python3.7/site-packages/tensorflow_core/python/keras/engine/training_v2.py\", line 646, in _process_inputs\n",
      "    x, y, sample_weight=sample_weights)\n",
      "  File \"/home/questionnote/miniconda3/envs/tensorflow/lib/python3.7/site-packages/tensorflow_core/python/keras/engine/training.py\", line 2383, in _standardize_user_data\n",
      "    batch_size=batch_size)\n",
      "  File \"/home/questionnote/miniconda3/envs/tensorflow/lib/python3.7/site-packages/tensorflow_core/python/keras/engine/training.py\", line 2489, in _standardize_tensors\n",
      "    y, self._feed_loss_fns, feed_output_shapes)\n",
      "  File \"/home/questionnote/miniconda3/envs/tensorflow/lib/python3.7/site-packages/tensorflow_core/python/keras/engine/training_utils.py\", line 810, in check_loss_and_target_compatibility\n",
      "    ' while using as loss `' + loss_name + '`. '\n",
      "ValueError: A target array with shape (42000, 10) was passed for an output of shape (None, 5) while using as loss `categorical_crossentropy`. This loss expects targets to have the same shape as the output.\n",
      "\n",
      "During handling of the above exception, another exception occurred:\n",
      "\n",
      "Traceback (most recent call last):\n",
      "  File \"/home/questionnote/miniconda3/envs/tensorflow/lib/python3.7/site-packages/IPython/core/interactiveshell.py\", line 2088, in showtraceback\n",
      "    stb = value._render_traceback_()\n",
      "AttributeError: 'ValueError' object has no attribute '_render_traceback_'\n",
      "\n",
      "During handling of the above exception, another exception occurred:\n",
      "\n",
      "Traceback (most recent call last):\n",
      "  File \"/home/questionnote/miniconda3/envs/tensorflow/lib/python3.7/site-packages/IPython/core/interactiveshell.py\", line 3444, in run_ast_nodes\n",
      "    if (await self.run_code(code, result,  async_=asy)):\n",
      "  File \"/home/questionnote/miniconda3/envs/tensorflow/lib/python3.7/site-packages/IPython/core/interactiveshell.py\", line 3541, in run_code\n",
      "    self.showtraceback(running_compiled_code=True)\n",
      "  File \"/home/questionnote/miniconda3/envs/tensorflow/lib/python3.7/site-packages/IPython/core/interactiveshell.py\", line 2091, in showtraceback\n",
      "    value, tb, tb_offset=tb_offset)\n",
      "  File \"/home/questionnote/miniconda3/envs/tensorflow/lib/python3.7/site-packages/IPython/core/ultratb.py\", line 1368, in structured_traceback\n",
      "    self, etype, value, tb, tb_offset, number_of_lines_of_context)\n",
      "  File \"/home/questionnote/miniconda3/envs/tensorflow/lib/python3.7/site-packages/IPython/core/ultratb.py\", line 1268, in structured_traceback\n",
      "    self, etype, value, tb, tb_offset, number_of_lines_of_context\n",
      "  File \"/home/questionnote/miniconda3/envs/tensorflow/lib/python3.7/site-packages/IPython/core/ultratb.py\", line 1125, in structured_traceback\n",
      "    tb_offset)\n",
      "  File \"/home/questionnote/miniconda3/envs/tensorflow/lib/python3.7/site-packages/IPython/core/ultratb.py\", line 1082, in format_exception_as_a_whole\n",
      "    last_unique, recursion_repeat = find_recursion(orig_etype, evalue, records)\n",
      "  File \"/home/questionnote/miniconda3/envs/tensorflow/lib/python3.7/site-packages/IPython/core/ultratb.py\", line 382, in find_recursion\n",
      "    return len(records), 0\n",
      "TypeError: object of type 'NoneType' has no len()\n",
      "\n",
      "During handling of the above exception, another exception occurred:\n",
      "\n",
      "Traceback (most recent call last):\n",
      "  File \"/home/questionnote/miniconda3/envs/tensorflow/lib/python3.7/site-packages/IPython/core/interactiveshell.py\", line 2088, in showtraceback\n",
      "    stb = value._render_traceback_()\n",
      "AttributeError: 'TypeError' object has no attribute '_render_traceback_'\n",
      "\n",
      "During handling of the above exception, another exception occurred:\n",
      "\n",
      "Traceback (most recent call last):\n",
      "  File \"/home/questionnote/miniconda3/envs/tensorflow/lib/python3.7/site-packages/IPython/core/interactiveshell.py\", line 3003, in _run_cell\n",
      "    return runner(coro)\n",
      "  File \"/home/questionnote/miniconda3/envs/tensorflow/lib/python3.7/site-packages/IPython/core/async_helpers.py\", line 78, in _pseudo_sync_runner\n",
      "    coro.send(None)\n",
      "  File \"/home/questionnote/miniconda3/envs/tensorflow/lib/python3.7/site-packages/IPython/core/interactiveshell.py\", line 3229, in run_cell_async\n",
      "    interactivity=interactivity, compiler=compiler, result=result)\n",
      "  File \"/home/questionnote/miniconda3/envs/tensorflow/lib/python3.7/site-packages/IPython/core/interactiveshell.py\", line 3463, in run_ast_nodes\n",
      "    self.showtraceback()\n",
      "  File \"/home/questionnote/miniconda3/envs/tensorflow/lib/python3.7/site-packages/IPython/core/interactiveshell.py\", line 2091, in showtraceback\n",
      "    value, tb, tb_offset=tb_offset)\n",
      "  File \"/home/questionnote/miniconda3/envs/tensorflow/lib/python3.7/site-packages/IPython/core/ultratb.py\", line 1368, in structured_traceback\n",
      "    self, etype, value, tb, tb_offset, number_of_lines_of_context)\n",
      "  File \"/home/questionnote/miniconda3/envs/tensorflow/lib/python3.7/site-packages/IPython/core/ultratb.py\", line 1268, in structured_traceback\n",
      "    self, etype, value, tb, tb_offset, number_of_lines_of_context\n",
      "  File \"/home/questionnote/miniconda3/envs/tensorflow/lib/python3.7/site-packages/IPython/core/ultratb.py\", line 1143, in structured_traceback\n",
      "    chained_exceptions_tb_offset)\n",
      "  File \"/home/questionnote/miniconda3/envs/tensorflow/lib/python3.7/site-packages/IPython/core/ultratb.py\", line 1082, in format_exception_as_a_whole\n",
      "    last_unique, recursion_repeat = find_recursion(orig_etype, evalue, records)\n",
      "  File \"/home/questionnote/miniconda3/envs/tensorflow/lib/python3.7/site-packages/IPython/core/ultratb.py\", line 382, in find_recursion\n",
      "    return len(records), 0\n",
      "TypeError: object of type 'NoneType' has no len()\n",
      "\n",
      "During handling of the above exception, another exception occurred:\n",
      "\n",
      "Traceback (most recent call last):\n",
      "  File \"/home/questionnote/miniconda3/envs/tensorflow/lib/python3.7/site-packages/IPython/core/interactiveshell.py\", line 2088, in showtraceback\n",
      "    stb = value._render_traceback_()\n",
      "AttributeError: 'TypeError' object has no attribute '_render_traceback_'\n",
      "\n",
      "During handling of the above exception, another exception occurred:\n",
      "\n",
      "Traceback (most recent call last):\n",
      "  File \"/home/questionnote/miniconda3/envs/tensorflow/lib/python3.7/site-packages/IPython/core/ultratb.py\", line 1101, in get_records\n",
      "    return _fixed_getinnerframes(etb, number_of_lines_of_context, tb_offset)\n",
      "  File \"/home/questionnote/miniconda3/envs/tensorflow/lib/python3.7/site-packages/IPython/core/ultratb.py\", line 248, in wrapped\n",
      "    return f(*args, **kwargs)\n",
      "  File \"/home/questionnote/miniconda3/envs/tensorflow/lib/python3.7/site-packages/IPython/core/ultratb.py\", line 281, in _fixed_getinnerframes\n",
      "    records = fix_frame_records_filenames(inspect.getinnerframes(etb, context))\n",
      "  File \"/home/questionnote/miniconda3/envs/tensorflow/lib/python3.7/inspect.py\", line 1502, in getinnerframes\n",
      "    frameinfo = (tb.tb_frame,) + getframeinfo(tb, context)\n",
      "  File \"/home/questionnote/miniconda3/envs/tensorflow/lib/python3.7/inspect.py\", line 1460, in getframeinfo\n",
      "    filename = getsourcefile(frame) or getfile(frame)\n",
      "  File \"/home/questionnote/miniconda3/envs/tensorflow/lib/python3.7/inspect.py\", line 696, in getsourcefile\n",
      "    if getattr(getmodule(object, filename), '__loader__', None) is not None:\n",
      "  File \"/home/questionnote/miniconda3/envs/tensorflow/lib/python3.7/inspect.py\", line 733, in getmodule\n",
      "    if ismodule(module) and hasattr(module, '__file__'):\n",
      "  File \"/home/questionnote/miniconda3/envs/tensorflow/lib/python3.7/site-packages/tensorflow/__init__.py\", line 50, in __getattr__\n",
      "    module = self._load()\n",
      "  File \"/home/questionnote/miniconda3/envs/tensorflow/lib/python3.7/site-packages/tensorflow/__init__.py\", line 44, in _load\n",
      "    module = _importlib.import_module(self.__name__)\n",
      "  File \"/home/questionnote/miniconda3/envs/tensorflow/lib/python3.7/importlib/__init__.py\", line 127, in import_module\n",
      "    return _bootstrap._gcd_import(name[level:], package, level)\n",
      "  File \"<frozen importlib._bootstrap>\", line 1006, in _gcd_import\n",
      "  File \"<frozen importlib._bootstrap>\", line 983, in _find_and_load\n",
      "  File \"<frozen importlib._bootstrap>\", line 965, in _find_and_load_unlocked\n",
      "ModuleNotFoundError: No module named 'tensorflow_core.estimator'\n"
     ]
    }
   ],
   "source": [
    "history = cnn_fmodel.fit(trnx_reshape, trny, validation_data = [tstx_reshape, tsty], batch_size = 10, epochs = 10)"
   ]
  }
 ],
 "metadata": {
  "kernelspec": {
   "display_name": "Python 3 (ipykernel)",
   "language": "python",
   "name": "python3"
  },
  "language_info": {
   "codemirror_mode": {
    "name": "ipython",
    "version": 3
   },
   "file_extension": ".py",
   "mimetype": "text/x-python",
   "name": "python",
   "nbconvert_exporter": "python",
   "pygments_lexer": "ipython3",
   "version": "3.7.12"
  }
 },
 "nbformat": 4,
 "nbformat_minor": 5
}
