{
 "cells": [
  {
   "cell_type": "code",
   "execution_count": 15,
   "id": "9728c63b",
   "metadata": {},
   "outputs": [],
   "source": [
    "import numpy as np\n",
    "import pandas as pd\n",
    "import matplotlib.pyplot as plt\n",
    "%matplotlib inline\n",
    "\n",
    "from os.path import join\n",
    "\n",
    "import tensorflow as tf \n",
    "from tensorflow.keras import layers, models, optimizers, Input, Model\n",
    "from tensorflow.keras.utils import to_categorical"
   ]
  },
  {
   "cell_type": "code",
   "execution_count": 16,
   "id": "237f1593",
   "metadata": {},
   "outputs": [],
   "source": [
    "datax = np.load(join('data', 'MNIST.npy'))\n",
    "datay = np.load(join('data', 'Label.npy'))"
   ]
  },
  {
   "cell_type": "code",
   "execution_count": 17,
   "id": "97605852",
   "metadata": {},
   "outputs": [
    {
     "name": "stdout",
     "output_type": "stream",
     "text": [
      "최대 : 1.0, 최소 : 0.0\n"
     ]
    }
   ],
   "source": [
    "datax_norm = datax/255\n",
    "print('최대 : {}, 최소 : {}'.format(np.max(datax_norm), np.min(datax_norm)))"
   ]
  },
  {
   "cell_type": "code",
   "execution_count": 18,
   "id": "1b6cc029",
   "metadata": {},
   "outputs": [
    {
     "name": "stdout",
     "output_type": "stream",
     "text": [
      "[5 0 4 1 9 2 1 3 1 4]\n",
      "[[0. 0. 0. 0. 0. 1. 0. 0. 0. 0.]\n",
      " [1. 0. 0. 0. 0. 0. 0. 0. 0. 0.]\n",
      " [0. 0. 0. 0. 1. 0. 0. 0. 0. 0.]\n",
      " [0. 1. 0. 0. 0. 0. 0. 0. 0. 0.]\n",
      " [0. 0. 0. 0. 0. 0. 0. 0. 0. 1.]\n",
      " [0. 0. 1. 0. 0. 0. 0. 0. 0. 0.]\n",
      " [0. 1. 0. 0. 0. 0. 0. 0. 0. 0.]\n",
      " [0. 0. 0. 1. 0. 0. 0. 0. 0. 0.]\n",
      " [0. 1. 0. 0. 0. 0. 0. 0. 0. 0.]\n",
      " [0. 0. 0. 0. 1. 0. 0. 0. 0. 0.]]\n"
     ]
    }
   ],
   "source": [
    "datay_onehot = to_categorical(datay)\n",
    "print(datay[0:10])\n",
    "print(datay_onehot[0:10,:])"
   ]
  },
  {
   "cell_type": "code",
   "execution_count": 19,
   "id": "eb93f2cd",
   "metadata": {},
   "outputs": [],
   "source": [
    "from sklearn.model_selection import train_test_split\n",
    "trnx, tstx, trny, tsty = train_test_split(datax_norm, datay_onehot, test_size = 0.3, random_state = 111)"
   ]
  },
  {
   "cell_type": "code",
   "execution_count": 20,
   "id": "c768f4ba",
   "metadata": {},
   "outputs": [
    {
     "name": "stdout",
     "output_type": "stream",
     "text": [
      "(42000, 28, 28)\n",
      "(42000, 10)\n"
     ]
    }
   ],
   "source": [
    "print(trnx.shape)\n",
    "print(trny.shape)"
   ]
  },
  {
   "cell_type": "code",
   "execution_count": 21,
   "id": "3ca025ab",
   "metadata": {},
   "outputs": [
    {
     "data": {
      "text/plain": [
       "(42000, 28, 28, 1)"
      ]
     },
     "execution_count": 21,
     "metadata": {},
     "output_type": "execute_result"
    }
   ],
   "source": [
    "trnx_reshape = trnx.reshape(-1,28,28,1)\n",
    "tstx_reshape = tstx.reshape(-1,28,28,1)\n",
    "trnx_reshape.shape"
   ]
  },
  {
   "cell_type": "code",
   "execution_count": 22,
   "id": "3b81db3a",
   "metadata": {},
   "outputs": [],
   "source": [
    "def res_identity(x, filters):\n",
    "    x_skip = x\n",
    "    f1, f2 = filters\n",
    "    \n",
    "    x = layers.Conv2D(f1, kernel_size = (1, 1), strides=(1, 1), padding='valid')(x)\n",
    "    x = layers.BatchNormalization()(x)\n",
    "    x = layers.Activation(\"relu\")(x)\n",
    "    \n",
    "    x = layers.Conv2D(f1, kernel_size = (3, 3), strides=(1, 1), padding = 'same')(x)\n",
    "    x = layers.BatchNormalization()(x)\n",
    "    x = layers.Activation(\"relu\")(x)\n",
    "    \n",
    "    x = layers.Conv2D(f2, kernel_size = (1, 1), strides=(1, 1), padding = 'valid')(x)\n",
    "    x = layers.BatchNormalization()(x)\n",
    "    #x = layers.Activation(\"relu\")(x)\n",
    "    \n",
    "    x = layers.Add()[x,x_skip]\n",
    "    x = layers.Activation(\"relu\")(x)\n",
    "    \n",
    "    return x"
   ]
  },
  {
   "cell_type": "code",
   "execution_count": 23,
   "id": "049f3540",
   "metadata": {},
   "outputs": [],
   "source": [
    "def res_conv(x, s, filters):\n",
    "    x_skip = x\n",
    "    f1, f2 = filters\n",
    "    \n",
    "    x = layers.Conv2D(f1, kernel_size=(1,1), strides=(s,s), padding='valid')(x)\n",
    "    x = layers.BatchNormalization()(x)\n",
    "    x = layers.Activation('relu')(x)\n",
    "    \n",
    "    x = layers.Conv2D(f1, kernel_size=(3,3), strides=(1,1), padding='same')(x)\n",
    "    x = layers.BatchNormalization()(x)\n",
    "    x = layers.Activation('relu')(x)\n",
    "\n",
    "    x = layers.Conv2D(f2, kernel_size=(1,1), strides=(1,1), padding='valid')(x)\n",
    "    x = layers.BatchNormalization()(x)\n",
    "    \n",
    "    x_skip = layers.Conv2D(f2, kernel_size=(1,1), strides=(s,s), padding='valid')(x_skip)\n",
    "    x_skip = layers.BatchNormalization()(x_skip)\n",
    "    \n",
    "    x = layers.Add()[x, x_skip]\n",
    "    x = layers.Activation(\"relu\")(x)\n",
    "    \n",
    "    return x"
   ]
  },
  {
   "cell_type": "code",
   "execution_count": 12,
   "id": "7b02a62e",
   "metadata": {},
   "outputs": [],
   "source": [
    "def resnet50():\n",
    "    input_im = input(shape=(trnx_reshape.shape[1], trnx_reshape.shape[2], trnx_reshape.shape[3]))\n",
    "    x = layers.ZeroPadding2D(padding=(3, 3))(input_im)\n",
    "\n",
    "    x = layers.Conv2D(64, kernel_size=(7,7), strides=(2,2))(x)\n",
    "    x = layers.BatchNormalization()(x)\n",
    "    x = layers.Activation(\"relu\")(x)\n",
    "    x = layers.MaxPooling2D((3, 3), strides=(2,2))(x)\n",
    "    \n",
    "    x = res_conv(x, s=1, filters=(64,256))\n",
    "    x = res_identity(x, filters=(64,256))\n",
    "    x = res_identity(x, filters=(64,256))\n",
    "    \n",
    "    x = res_conv(x, s=2, filters=(128,512))\n",
    "    x = res_identity(x, filters=(128,512))\n",
    "    x = res_identity(x, filters=(128,512))\n",
    "    x = res_identity(x, filters=(128,512))\n",
    "\n",
    "    x = res_conv(x, s=2, filters=(256,1024))\n",
    "    x = res_identity(x, filters=(256,1024))\n",
    "    x = res_identity(x, filters=(256,1024))\n",
    "    x = res_identity(x, filters=(256,1024))\n",
    "    x = res_identity(x, filters=(256,1024))\n",
    "    x = res_identity(x, filters=(256,1024))\n",
    "    \n",
    "    x = res_conv(x, s=2, filters=(512,2048))\n",
    "    x = res_identity(x, filters=(512,2048))\n",
    "    x = res_identity(x, filters=(512,2048))\n",
    "    \n",
    "    x = layers.AveragePooling2D((2,2), padding='same')(x)\n",
    "    \n",
    "    x = layers.Flatten()(x)\n",
    "    x = layers.Dense(trny.shape[1], activation='softmax', kernel_initializer='he_normal')(x)\n",
    "    \n",
    "    model = Mode(inputs=input_im, outputs=x, name='Resnet50')\n",
    "    \n",
    "    return model"
   ]
  },
  {
   "cell_type": "code",
   "execution_count": null,
   "id": "fc1fc683",
   "metadata": {},
   "outputs": [
    {
     "name": "stderr",
     "output_type": "stream",
     "text": [
      "ERROR:root:Internal Python error in the inspect module.\n",
      "Below is the traceback from this internal error.\n",
      "\n",
      "ERROR:root:Internal Python error in the inspect module.\n",
      "Below is the traceback from this internal error.\n",
      "\n",
      "ERROR:root:Internal Python error in the inspect module.\n",
      "Below is the traceback from this internal error.\n",
      "\n"
     ]
    },
    {
     "name": "stdout",
     "output_type": "stream",
     "text": [
      "Traceback (most recent call last):\n",
      "  File \"/home/questionnote/miniconda3/envs/tensorflow/lib/python3.7/site-packages/IPython/core/interactiveshell.py\", line 3524, in run_code\n",
      "    exec(code_obj, self.user_global_ns, self.user_ns)\n",
      "  File \"/tmp/ipykernel_9215/287772904.py\", line 1, in <module>\n",
      "    resnet_model = resnet50()\n",
      "  File \"/tmp/ipykernel_9215/2533550262.py\", line 2, in resnet50\n",
      "    input_im = input(shape=(trnx_reshape.shape[1], trnx_reshape.shape[2], trnx_reshape.shape[3]))\n",
      "TypeError: raw_input() got an unexpected keyword argument 'shape'\n",
      "\n",
      "During handling of the above exception, another exception occurred:\n",
      "\n",
      "Traceback (most recent call last):\n",
      "  File \"/home/questionnote/miniconda3/envs/tensorflow/lib/python3.7/site-packages/IPython/core/interactiveshell.py\", line 2088, in showtraceback\n",
      "    stb = value._render_traceback_()\n",
      "AttributeError: 'TypeError' object has no attribute '_render_traceback_'\n",
      "\n",
      "During handling of the above exception, another exception occurred:\n",
      "\n",
      "Traceback (most recent call last):\n",
      "  File \"/home/questionnote/miniconda3/envs/tensorflow/lib/python3.7/site-packages/IPython/core/ultratb.py\", line 1101, in get_records\n",
      "    return _fixed_getinnerframes(etb, number_of_lines_of_context, tb_offset)\n",
      "  File \"/home/questionnote/miniconda3/envs/tensorflow/lib/python3.7/site-packages/IPython/core/ultratb.py\", line 248, in wrapped\n",
      "    return f(*args, **kwargs)\n",
      "  File \"/home/questionnote/miniconda3/envs/tensorflow/lib/python3.7/site-packages/IPython/core/ultratb.py\", line 281, in _fixed_getinnerframes\n",
      "    records = fix_frame_records_filenames(inspect.getinnerframes(etb, context))\n",
      "  File \"/home/questionnote/miniconda3/envs/tensorflow/lib/python3.7/inspect.py\", line 1502, in getinnerframes\n",
      "    frameinfo = (tb.tb_frame,) + getframeinfo(tb, context)\n",
      "  File \"/home/questionnote/miniconda3/envs/tensorflow/lib/python3.7/inspect.py\", line 1460, in getframeinfo\n",
      "    filename = getsourcefile(frame) or getfile(frame)\n",
      "  File \"/home/questionnote/miniconda3/envs/tensorflow/lib/python3.7/inspect.py\", line 696, in getsourcefile\n",
      "    if getattr(getmodule(object, filename), '__loader__', None) is not None:\n",
      "  File \"/home/questionnote/miniconda3/envs/tensorflow/lib/python3.7/inspect.py\", line 733, in getmodule\n",
      "    if ismodule(module) and hasattr(module, '__file__'):\n",
      "  File \"/home/questionnote/miniconda3/envs/tensorflow/lib/python3.7/site-packages/tensorflow/__init__.py\", line 50, in __getattr__\n",
      "    module = self._load()\n",
      "  File \"/home/questionnote/miniconda3/envs/tensorflow/lib/python3.7/site-packages/tensorflow/__init__.py\", line 44, in _load\n",
      "    module = _importlib.import_module(self.__name__)\n",
      "  File \"/home/questionnote/miniconda3/envs/tensorflow/lib/python3.7/importlib/__init__.py\", line 127, in import_module\n",
      "    return _bootstrap._gcd_import(name[level:], package, level)\n",
      "  File \"<frozen importlib._bootstrap>\", line 1006, in _gcd_import\n",
      "  File \"<frozen importlib._bootstrap>\", line 983, in _find_and_load\n",
      "  File \"<frozen importlib._bootstrap>\", line 965, in _find_and_load_unlocked\n",
      "ModuleNotFoundError: No module named 'tensorflow_core.estimator'\n",
      "Traceback (most recent call last):\n",
      "  File \"/home/questionnote/miniconda3/envs/tensorflow/lib/python3.7/site-packages/IPython/core/interactiveshell.py\", line 3524, in run_code\n",
      "    exec(code_obj, self.user_global_ns, self.user_ns)\n",
      "  File \"/tmp/ipykernel_9215/287772904.py\", line 1, in <module>\n",
      "    resnet_model = resnet50()\n",
      "  File \"/tmp/ipykernel_9215/2533550262.py\", line 2, in resnet50\n",
      "    input_im = input(shape=(trnx_reshape.shape[1], trnx_reshape.shape[2], trnx_reshape.shape[3]))\n",
      "TypeError: raw_input() got an unexpected keyword argument 'shape'\n",
      "\n",
      "During handling of the above exception, another exception occurred:\n",
      "\n",
      "Traceback (most recent call last):\n",
      "  File \"/home/questionnote/miniconda3/envs/tensorflow/lib/python3.7/site-packages/IPython/core/interactiveshell.py\", line 2088, in showtraceback\n",
      "    stb = value._render_traceback_()\n",
      "AttributeError: 'TypeError' object has no attribute '_render_traceback_'\n",
      "\n",
      "During handling of the above exception, another exception occurred:\n",
      "\n",
      "Traceback (most recent call last):\n",
      "  File \"/home/questionnote/miniconda3/envs/tensorflow/lib/python3.7/site-packages/IPython/core/interactiveshell.py\", line 3444, in run_ast_nodes\n",
      "    if (await self.run_code(code, result,  async_=asy)):\n",
      "  File \"/home/questionnote/miniconda3/envs/tensorflow/lib/python3.7/site-packages/IPython/core/interactiveshell.py\", line 3541, in run_code\n",
      "    self.showtraceback(running_compiled_code=True)\n",
      "  File \"/home/questionnote/miniconda3/envs/tensorflow/lib/python3.7/site-packages/IPython/core/interactiveshell.py\", line 2091, in showtraceback\n",
      "    value, tb, tb_offset=tb_offset)\n",
      "  File \"/home/questionnote/miniconda3/envs/tensorflow/lib/python3.7/site-packages/IPython/core/ultratb.py\", line 1368, in structured_traceback\n",
      "    self, etype, value, tb, tb_offset, number_of_lines_of_context)\n",
      "  File \"/home/questionnote/miniconda3/envs/tensorflow/lib/python3.7/site-packages/IPython/core/ultratb.py\", line 1268, in structured_traceback\n",
      "    self, etype, value, tb, tb_offset, number_of_lines_of_context\n",
      "  File \"/home/questionnote/miniconda3/envs/tensorflow/lib/python3.7/site-packages/IPython/core/ultratb.py\", line 1125, in structured_traceback\n",
      "    tb_offset)\n",
      "  File \"/home/questionnote/miniconda3/envs/tensorflow/lib/python3.7/site-packages/IPython/core/ultratb.py\", line 1082, in format_exception_as_a_whole\n",
      "    last_unique, recursion_repeat = find_recursion(orig_etype, evalue, records)\n",
      "  File \"/home/questionnote/miniconda3/envs/tensorflow/lib/python3.7/site-packages/IPython/core/ultratb.py\", line 382, in find_recursion\n",
      "    return len(records), 0\n",
      "TypeError: object of type 'NoneType' has no len()\n",
      "\n",
      "During handling of the above exception, another exception occurred:\n",
      "\n",
      "Traceback (most recent call last):\n",
      "  File \"/home/questionnote/miniconda3/envs/tensorflow/lib/python3.7/site-packages/IPython/core/interactiveshell.py\", line 2088, in showtraceback\n",
      "    stb = value._render_traceback_()\n",
      "AttributeError: 'TypeError' object has no attribute '_render_traceback_'\n",
      "\n",
      "During handling of the above exception, another exception occurred:\n",
      "\n",
      "Traceback (most recent call last):\n",
      "  File \"/home/questionnote/miniconda3/envs/tensorflow/lib/python3.7/site-packages/IPython/core/ultratb.py\", line 1101, in get_records\n",
      "    return _fixed_getinnerframes(etb, number_of_lines_of_context, tb_offset)\n",
      "  File \"/home/questionnote/miniconda3/envs/tensorflow/lib/python3.7/site-packages/IPython/core/ultratb.py\", line 248, in wrapped\n",
      "    return f(*args, **kwargs)\n",
      "  File \"/home/questionnote/miniconda3/envs/tensorflow/lib/python3.7/site-packages/IPython/core/ultratb.py\", line 281, in _fixed_getinnerframes\n",
      "    records = fix_frame_records_filenames(inspect.getinnerframes(etb, context))\n",
      "  File \"/home/questionnote/miniconda3/envs/tensorflow/lib/python3.7/inspect.py\", line 1502, in getinnerframes\n",
      "    frameinfo = (tb.tb_frame,) + getframeinfo(tb, context)\n",
      "  File \"/home/questionnote/miniconda3/envs/tensorflow/lib/python3.7/inspect.py\", line 1460, in getframeinfo\n",
      "    filename = getsourcefile(frame) or getfile(frame)\n",
      "  File \"/home/questionnote/miniconda3/envs/tensorflow/lib/python3.7/inspect.py\", line 696, in getsourcefile\n",
      "    if getattr(getmodule(object, filename), '__loader__', None) is not None:\n",
      "  File \"/home/questionnote/miniconda3/envs/tensorflow/lib/python3.7/inspect.py\", line 733, in getmodule\n",
      "    if ismodule(module) and hasattr(module, '__file__'):\n",
      "  File \"/home/questionnote/miniconda3/envs/tensorflow/lib/python3.7/site-packages/tensorflow/__init__.py\", line 50, in __getattr__\n",
      "    module = self._load()\n",
      "  File \"/home/questionnote/miniconda3/envs/tensorflow/lib/python3.7/site-packages/tensorflow/__init__.py\", line 44, in _load\n",
      "    module = _importlib.import_module(self.__name__)\n",
      "  File \"/home/questionnote/miniconda3/envs/tensorflow/lib/python3.7/importlib/__init__.py\", line 127, in import_module\n",
      "    return _bootstrap._gcd_import(name[level:], package, level)\n",
      "  File \"<frozen importlib._bootstrap>\", line 1006, in _gcd_import\n",
      "  File \"<frozen importlib._bootstrap>\", line 983, in _find_and_load\n",
      "  File \"<frozen importlib._bootstrap>\", line 965, in _find_and_load_unlocked\n",
      "ModuleNotFoundError: No module named 'tensorflow_core.estimator'\n",
      "ERROR! Session/line number was not unique in database. History logging moved to new session 151\n",
      "Traceback (most recent call last):\n",
      "  File \"/home/questionnote/miniconda3/envs/tensorflow/lib/python3.7/site-packages/IPython/core/interactiveshell.py\", line 3524, in run_code\n",
      "    exec(code_obj, self.user_global_ns, self.user_ns)\n",
      "  File \"/tmp/ipykernel_9215/287772904.py\", line 1, in <module>\n",
      "    resnet_model = resnet50()\n",
      "  File \"/tmp/ipykernel_9215/2533550262.py\", line 2, in resnet50\n",
      "    input_im = input(shape=(trnx_reshape.shape[1], trnx_reshape.shape[2], trnx_reshape.shape[3]))\n",
      "TypeError: raw_input() got an unexpected keyword argument 'shape'\n",
      "\n",
      "During handling of the above exception, another exception occurred:\n",
      "\n",
      "Traceback (most recent call last):\n",
      "  File \"/home/questionnote/miniconda3/envs/tensorflow/lib/python3.7/site-packages/IPython/core/interactiveshell.py\", line 2088, in showtraceback\n",
      "    stb = value._render_traceback_()\n",
      "AttributeError: 'TypeError' object has no attribute '_render_traceback_'\n",
      "\n",
      "During handling of the above exception, another exception occurred:\n",
      "\n",
      "Traceback (most recent call last):\n",
      "  File \"/home/questionnote/miniconda3/envs/tensorflow/lib/python3.7/site-packages/IPython/core/interactiveshell.py\", line 3444, in run_ast_nodes\n",
      "    if (await self.run_code(code, result,  async_=asy)):\n",
      "  File \"/home/questionnote/miniconda3/envs/tensorflow/lib/python3.7/site-packages/IPython/core/interactiveshell.py\", line 3541, in run_code\n",
      "    self.showtraceback(running_compiled_code=True)\n",
      "  File \"/home/questionnote/miniconda3/envs/tensorflow/lib/python3.7/site-packages/IPython/core/interactiveshell.py\", line 2091, in showtraceback\n",
      "    value, tb, tb_offset=tb_offset)\n",
      "  File \"/home/questionnote/miniconda3/envs/tensorflow/lib/python3.7/site-packages/IPython/core/ultratb.py\", line 1368, in structured_traceback\n",
      "    self, etype, value, tb, tb_offset, number_of_lines_of_context)\n",
      "  File \"/home/questionnote/miniconda3/envs/tensorflow/lib/python3.7/site-packages/IPython/core/ultratb.py\", line 1268, in structured_traceback\n",
      "    self, etype, value, tb, tb_offset, number_of_lines_of_context\n",
      "  File \"/home/questionnote/miniconda3/envs/tensorflow/lib/python3.7/site-packages/IPython/core/ultratb.py\", line 1125, in structured_traceback\n",
      "    tb_offset)\n",
      "  File \"/home/questionnote/miniconda3/envs/tensorflow/lib/python3.7/site-packages/IPython/core/ultratb.py\", line 1082, in format_exception_as_a_whole\n",
      "    last_unique, recursion_repeat = find_recursion(orig_etype, evalue, records)\n",
      "  File \"/home/questionnote/miniconda3/envs/tensorflow/lib/python3.7/site-packages/IPython/core/ultratb.py\", line 382, in find_recursion\n",
      "    return len(records), 0\n",
      "TypeError: object of type 'NoneType' has no len()\n",
      "\n",
      "During handling of the above exception, another exception occurred:\n",
      "\n",
      "Traceback (most recent call last):\n",
      "  File \"/home/questionnote/miniconda3/envs/tensorflow/lib/python3.7/site-packages/IPython/core/interactiveshell.py\", line 2088, in showtraceback\n",
      "    stb = value._render_traceback_()\n",
      "AttributeError: 'TypeError' object has no attribute '_render_traceback_'\n",
      "\n",
      "During handling of the above exception, another exception occurred:\n",
      "\n",
      "Traceback (most recent call last):\n",
      "  File \"/home/questionnote/miniconda3/envs/tensorflow/lib/python3.7/site-packages/IPython/core/interactiveshell.py\", line 3003, in _run_cell\n",
      "    return runner(coro)\n",
      "  File \"/home/questionnote/miniconda3/envs/tensorflow/lib/python3.7/site-packages/IPython/core/async_helpers.py\", line 78, in _pseudo_sync_runner\n",
      "    coro.send(None)\n",
      "  File \"/home/questionnote/miniconda3/envs/tensorflow/lib/python3.7/site-packages/IPython/core/interactiveshell.py\", line 3229, in run_cell_async\n",
      "    interactivity=interactivity, compiler=compiler, result=result)\n",
      "  File \"/home/questionnote/miniconda3/envs/tensorflow/lib/python3.7/site-packages/IPython/core/interactiveshell.py\", line 3463, in run_ast_nodes\n",
      "    self.showtraceback()\n",
      "  File \"/home/questionnote/miniconda3/envs/tensorflow/lib/python3.7/site-packages/IPython/core/interactiveshell.py\", line 2091, in showtraceback\n",
      "    value, tb, tb_offset=tb_offset)\n",
      "  File \"/home/questionnote/miniconda3/envs/tensorflow/lib/python3.7/site-packages/IPython/core/ultratb.py\", line 1368, in structured_traceback\n",
      "    self, etype, value, tb, tb_offset, number_of_lines_of_context)\n",
      "  File \"/home/questionnote/miniconda3/envs/tensorflow/lib/python3.7/site-packages/IPython/core/ultratb.py\", line 1268, in structured_traceback\n",
      "    self, etype, value, tb, tb_offset, number_of_lines_of_context\n",
      "  File \"/home/questionnote/miniconda3/envs/tensorflow/lib/python3.7/site-packages/IPython/core/ultratb.py\", line 1143, in structured_traceback\n",
      "    chained_exceptions_tb_offset)\n",
      "  File \"/home/questionnote/miniconda3/envs/tensorflow/lib/python3.7/site-packages/IPython/core/ultratb.py\", line 1082, in format_exception_as_a_whole\n",
      "    last_unique, recursion_repeat = find_recursion(orig_etype, evalue, records)\n",
      "  File \"/home/questionnote/miniconda3/envs/tensorflow/lib/python3.7/site-packages/IPython/core/ultratb.py\", line 382, in find_recursion\n",
      "    return len(records), 0\n",
      "TypeError: object of type 'NoneType' has no len()\n",
      "\n",
      "During handling of the above exception, another exception occurred:\n",
      "\n",
      "Traceback (most recent call last):\n",
      "  File \"/home/questionnote/miniconda3/envs/tensorflow/lib/python3.7/site-packages/IPython/core/interactiveshell.py\", line 2088, in showtraceback\n",
      "    stb = value._render_traceback_()\n",
      "AttributeError: 'TypeError' object has no attribute '_render_traceback_'\n",
      "\n",
      "During handling of the above exception, another exception occurred:\n",
      "\n",
      "Traceback (most recent call last):\n",
      "  File \"/home/questionnote/miniconda3/envs/tensorflow/lib/python3.7/site-packages/IPython/core/ultratb.py\", line 1101, in get_records\n",
      "    return _fixed_getinnerframes(etb, number_of_lines_of_context, tb_offset)\n",
      "  File \"/home/questionnote/miniconda3/envs/tensorflow/lib/python3.7/site-packages/IPython/core/ultratb.py\", line 248, in wrapped\n",
      "    return f(*args, **kwargs)\n",
      "  File \"/home/questionnote/miniconda3/envs/tensorflow/lib/python3.7/site-packages/IPython/core/ultratb.py\", line 281, in _fixed_getinnerframes\n",
      "    records = fix_frame_records_filenames(inspect.getinnerframes(etb, context))\n",
      "  File \"/home/questionnote/miniconda3/envs/tensorflow/lib/python3.7/inspect.py\", line 1502, in getinnerframes\n",
      "    frameinfo = (tb.tb_frame,) + getframeinfo(tb, context)\n",
      "  File \"/home/questionnote/miniconda3/envs/tensorflow/lib/python3.7/inspect.py\", line 1460, in getframeinfo\n",
      "    filename = getsourcefile(frame) or getfile(frame)\n",
      "  File \"/home/questionnote/miniconda3/envs/tensorflow/lib/python3.7/inspect.py\", line 696, in getsourcefile\n",
      "    if getattr(getmodule(object, filename), '__loader__', None) is not None:\n",
      "  File \"/home/questionnote/miniconda3/envs/tensorflow/lib/python3.7/inspect.py\", line 733, in getmodule\n",
      "    if ismodule(module) and hasattr(module, '__file__'):\n",
      "  File \"/home/questionnote/miniconda3/envs/tensorflow/lib/python3.7/site-packages/tensorflow/__init__.py\", line 50, in __getattr__\n",
      "    module = self._load()\n",
      "  File \"/home/questionnote/miniconda3/envs/tensorflow/lib/python3.7/site-packages/tensorflow/__init__.py\", line 44, in _load\n",
      "    module = _importlib.import_module(self.__name__)\n",
      "  File \"/home/questionnote/miniconda3/envs/tensorflow/lib/python3.7/importlib/__init__.py\", line 127, in import_module\n",
      "    return _bootstrap._gcd_import(name[level:], package, level)\n",
      "  File \"<frozen importlib._bootstrap>\", line 1006, in _gcd_import\n",
      "  File \"<frozen importlib._bootstrap>\", line 983, in _find_and_load\n",
      "  File \"<frozen importlib._bootstrap>\", line 965, in _find_and_load_unlocked\n",
      "ModuleNotFoundError: No module named 'tensorflow_core.estimator'\n"
     ]
    }
   ],
   "source": [
    "resnet_model = resnet50()\n"
   ]
  },
  {
   "cell_type": "code",
   "execution_count": 9,
   "id": "74cab01f",
   "metadata": {},
   "outputs": [
    {
     "name": "stderr",
     "output_type": "stream",
     "text": [
      "2022-05-04 13:11:02.955850: I tensorflow/stream_executor/platform/default/dso_loader.cc:44] Successfully opened dynamic library libcuda.so.1\n",
      "2022-05-04 13:11:03.007311: I tensorflow/stream_executor/cuda/cuda_gpu_executor.cc:981] successful NUMA node read from SysFS had negative value (-1), but there must be at least one NUMA node, so returning NUMA node zero\n",
      "2022-05-04 13:11:03.007516: I tensorflow/core/common_runtime/gpu/gpu_device.cc:1555] Found device 0 with properties: \n",
      "pciBusID: 0000:01:00.0 name: NVIDIA GeForce RTX 3050 computeCapability: 8.6\n",
      "coreClock: 1.845GHz coreCount: 20 deviceMemorySize: 7.79GiB deviceMemoryBandwidth: 208.65GiB/s\n",
      "2022-05-04 13:11:03.007812: I tensorflow/stream_executor/platform/default/dso_loader.cc:44] Successfully opened dynamic library libcudart.so.10.1\n",
      "2022-05-04 13:11:03.010067: I tensorflow/stream_executor/platform/default/dso_loader.cc:44] Successfully opened dynamic library libcublas.so.10\n",
      "2022-05-04 13:11:03.012770: I tensorflow/stream_executor/platform/default/dso_loader.cc:44] Successfully opened dynamic library libcufft.so.10\n",
      "2022-05-04 13:11:03.013326: I tensorflow/stream_executor/platform/default/dso_loader.cc:44] Successfully opened dynamic library libcurand.so.10\n",
      "2022-05-04 13:11:03.016134: I tensorflow/stream_executor/platform/default/dso_loader.cc:44] Successfully opened dynamic library libcusolver.so.10\n",
      "2022-05-04 13:11:03.017453: I tensorflow/stream_executor/platform/default/dso_loader.cc:44] Successfully opened dynamic library libcusparse.so.10\n",
      "2022-05-04 13:11:03.021181: I tensorflow/stream_executor/platform/default/dso_loader.cc:44] Successfully opened dynamic library libcudnn.so.7\n",
      "2022-05-04 13:11:03.021309: I tensorflow/stream_executor/cuda/cuda_gpu_executor.cc:981] successful NUMA node read from SysFS had negative value (-1), but there must be at least one NUMA node, so returning NUMA node zero\n",
      "2022-05-04 13:11:03.021463: I tensorflow/stream_executor/cuda/cuda_gpu_executor.cc:981] successful NUMA node read from SysFS had negative value (-1), but there must be at least one NUMA node, so returning NUMA node zero\n",
      "2022-05-04 13:11:03.021523: I tensorflow/core/common_runtime/gpu/gpu_device.cc:1697] Adding visible gpu devices: 0\n",
      "2022-05-04 13:11:03.021954: I tensorflow/core/platform/cpu_feature_guard.cc:142] Your CPU supports instructions that this TensorFlow binary was not compiled to use: SSE4.1 SSE4.2 AVX AVX2 FMA\n",
      "2022-05-04 13:11:03.026212: I tensorflow/core/platform/profile_utils/cpu_utils.cc:94] CPU Frequency: 3686400000 Hz\n",
      "2022-05-04 13:11:03.026489: I tensorflow/compiler/xla/service/service.cc:168] XLA service 0x55fb76b397a0 initialized for platform Host (this does not guarantee that XLA will be used). Devices:\n",
      "2022-05-04 13:11:03.026497: I tensorflow/compiler/xla/service/service.cc:176]   StreamExecutor device (0): Host, Default Version\n",
      "2022-05-04 13:11:03.090008: I tensorflow/stream_executor/cuda/cuda_gpu_executor.cc:981] successful NUMA node read from SysFS had negative value (-1), but there must be at least one NUMA node, so returning NUMA node zero\n",
      "2022-05-04 13:11:03.090113: I tensorflow/compiler/xla/service/service.cc:168] XLA service 0x55fb762f6a40 initialized for platform CUDA (this does not guarantee that XLA will be used). Devices:\n",
      "2022-05-04 13:11:03.090123: I tensorflow/compiler/xla/service/service.cc:176]   StreamExecutor device (0): NVIDIA GeForce RTX 3050, Compute Capability 8.6\n",
      "2022-05-04 13:11:03.090239: I tensorflow/stream_executor/cuda/cuda_gpu_executor.cc:981] successful NUMA node read from SysFS had negative value (-1), but there must be at least one NUMA node, so returning NUMA node zero\n",
      "2022-05-04 13:11:03.090297: I tensorflow/core/common_runtime/gpu/gpu_device.cc:1555] Found device 0 with properties: \n",
      "pciBusID: 0000:01:00.0 name: NVIDIA GeForce RTX 3050 computeCapability: 8.6\n",
      "coreClock: 1.845GHz coreCount: 20 deviceMemorySize: 7.79GiB deviceMemoryBandwidth: 208.65GiB/s\n",
      "2022-05-04 13:11:03.090322: I tensorflow/stream_executor/platform/default/dso_loader.cc:44] Successfully opened dynamic library libcudart.so.10.1\n",
      "2022-05-04 13:11:03.090328: I tensorflow/stream_executor/platform/default/dso_loader.cc:44] Successfully opened dynamic library libcublas.so.10\n",
      "2022-05-04 13:11:03.090334: I tensorflow/stream_executor/platform/default/dso_loader.cc:44] Successfully opened dynamic library libcufft.so.10\n",
      "2022-05-04 13:11:03.090340: I tensorflow/stream_executor/platform/default/dso_loader.cc:44] Successfully opened dynamic library libcurand.so.10\n",
      "2022-05-04 13:11:03.090345: I tensorflow/stream_executor/platform/default/dso_loader.cc:44] Successfully opened dynamic library libcusolver.so.10\n",
      "2022-05-04 13:11:03.090350: I tensorflow/stream_executor/platform/default/dso_loader.cc:44] Successfully opened dynamic library libcusparse.so.10\n",
      "2022-05-04 13:11:03.090355: I tensorflow/stream_executor/platform/default/dso_loader.cc:44] Successfully opened dynamic library libcudnn.so.7\n",
      "2022-05-04 13:11:03.090379: I tensorflow/stream_executor/cuda/cuda_gpu_executor.cc:981] successful NUMA node read from SysFS had negative value (-1), but there must be at least one NUMA node, so returning NUMA node zero\n",
      "2022-05-04 13:11:03.090484: I tensorflow/stream_executor/cuda/cuda_gpu_executor.cc:981] successful NUMA node read from SysFS had negative value (-1), but there must be at least one NUMA node, so returning NUMA node zero\n",
      "2022-05-04 13:11:03.090517: I tensorflow/core/common_runtime/gpu/gpu_device.cc:1697] Adding visible gpu devices: 0\n",
      "2022-05-04 13:11:03.090534: I tensorflow/stream_executor/platform/default/dso_loader.cc:44] Successfully opened dynamic library libcudart.so.10.1\n",
      "2022-05-04 13:11:03.090656: I tensorflow/core/common_runtime/gpu/gpu_device.cc:1096] Device interconnect StreamExecutor with strength 1 edge matrix:\n",
      "2022-05-04 13:11:03.090659: I tensorflow/core/common_runtime/gpu/gpu_device.cc:1102]      0 \n",
      "2022-05-04 13:11:03.090661: I tensorflow/core/common_runtime/gpu/gpu_device.cc:1115] 0:   N \n",
      "2022-05-04 13:11:03.090700: I tensorflow/stream_executor/cuda/cuda_gpu_executor.cc:981] successful NUMA node read from SysFS had negative value (-1), but there must be at least one NUMA node, so returning NUMA node zero\n",
      "2022-05-04 13:11:03.090750: I tensorflow/stream_executor/cuda/cuda_gpu_executor.cc:981] successful NUMA node read from SysFS had negative value (-1), but there must be at least one NUMA node, so returning NUMA node zero\n",
      "2022-05-04 13:11:03.090799: I tensorflow/core/common_runtime/gpu/gpu_device.cc:1241] Created TensorFlow device (/job:localhost/replica:0/task:0/device:GPU:0 with 7073 MB memory) -> physical GPU (device: 0, name: NVIDIA GeForce RTX 3050, pci bus id: 0000:01:00.0, compute capability: 8.6)\n"
     ]
    },
    {
     "name": "stdout",
     "output_type": "stream",
     "text": [
      "Model: \"sequential\"\n",
      "_________________________________________________________________\n",
      "Layer (type)                 Output Shape              Param #   \n",
      "=================================================================\n",
      "conv2d (Conv2D)              (None, 28, 28, 16)        80        \n",
      "_________________________________________________________________\n",
      "batch_normalization (BatchNo (None, 28, 28, 16)        64        \n",
      "_________________________________________________________________\n",
      "activation (Activation)      (None, 28, 28, 16)        0         \n",
      "_________________________________________________________________\n",
      "max_pooling2d (MaxPooling2D) (None, 14, 14, 16)        0         \n",
      "_________________________________________________________________\n",
      "conv2d_1 (Conv2D)            (None, 14, 14, 32)        2080      \n",
      "_________________________________________________________________\n",
      "batch_normalization_1 (Batch (None, 14, 14, 32)        128       \n",
      "_________________________________________________________________\n",
      "activation_1 (Activation)    (None, 14, 14, 32)        0         \n",
      "_________________________________________________________________\n",
      "dropout (Dropout)            (None, 14, 14, 32)        0         \n",
      "_________________________________________________________________\n",
      "max_pooling2d_1 (MaxPooling2 (None, 7, 7, 32)          0         \n",
      "_________________________________________________________________\n",
      "flatten (Flatten)            (None, 1568)              0         \n",
      "_________________________________________________________________\n",
      "dense (Dense)                (None, 128)               200832    \n",
      "_________________________________________________________________\n",
      "dense_1 (Dense)              (None, 10)                1290      \n",
      "=================================================================\n",
      "Total params: 204,474\n",
      "Trainable params: 204,378\n",
      "Non-trainable params: 96\n",
      "_________________________________________________________________\n"
     ]
    }
   ],
   "source": [
    "input_shape = (28, 28, 1)\n",
    "\n",
    "cnn_model = models.Sequential()\n",
    "\n",
    "cnn_model.add(layers.Conv2D(16, (2,2), padding = 'same', input_shape = input_shape))\n",
    "cnn_model.add(layers.BatchNormalization())\n",
    "cnn_model.add(layers.Activation(\"relu\"))\n",
    "cnn_model.add(layers.MaxPooling2D((2,2)))\n",
    "\n",
    "cnn_model.add(layers.Conv2D(32, (2,2), padding = 'same'))\n",
    "cnn_model.add(layers.BatchNormalization())\n",
    "cnn_model.add(layers.Activation(\"relu\"))\n",
    "cnn_model.add(layers.Dropout(0.2))\n",
    "cnn_model.add(layers.MaxPooling2D((2,2)))\n",
    "\n",
    "cnn_model.add(layers.Flatten())\n",
    "\n",
    "cnn_model.add(layers.Dense(units = 128, activation = 'relu'))\n",
    "cnn_model.add(layers.Dense(units = 10, activation = 'softmax'))\n",
    "\n",
    "cnn_model.compile(optimizer='Adam', loss = 'categorical_crossentropy', metrics=['accuracy'])\n",
    "cnn_model.summary()"
   ]
  },
  {
   "cell_type": "code",
   "execution_count": 10,
   "id": "dbb9451c",
   "metadata": {},
   "outputs": [
    {
     "data": {
      "text/plain": [
       "(42000, 28, 28, 1)"
      ]
     },
     "execution_count": 10,
     "metadata": {},
     "output_type": "execute_result"
    }
   ],
   "source": [
    "trnx_reshape = trnx.reshape(-1,28,28,1)\n",
    "tstx_reshape = tstx.reshape(-1,28,28,1)\n",
    "trnx_reshape.shape"
   ]
  },
  {
   "cell_type": "code",
   "execution_count": 1,
   "id": "08e424c3",
   "metadata": {},
   "outputs": [
    {
     "ename": "NameError",
     "evalue": "name 'cnn_model' is not defined",
     "output_type": "error",
     "traceback": [
      "\u001b[0;31m---------------------------------------------------------------------------\u001b[0m",
      "\u001b[0;31mNameError\u001b[0m                                 Traceback (most recent call last)",
      "\u001b[0;32m/tmp/ipykernel_8669/3041976857.py\u001b[0m in \u001b[0;36m<module>\u001b[0;34m\u001b[0m\n\u001b[0;32m----> 1\u001b[0;31m \u001b[0mhistory\u001b[0m \u001b[0;34m=\u001b[0m \u001b[0mcnn_model\u001b[0m\u001b[0;34m.\u001b[0m\u001b[0mfit\u001b[0m\u001b[0;34m(\u001b[0m\u001b[0mtrnx_reshape\u001b[0m\u001b[0;34m,\u001b[0m \u001b[0mtrny\u001b[0m\u001b[0;34m,\u001b[0m \u001b[0mvalidation_data\u001b[0m \u001b[0;34m=\u001b[0m \u001b[0;34m[\u001b[0m\u001b[0mtstx_reshape\u001b[0m\u001b[0;34m,\u001b[0m \u001b[0mtsty\u001b[0m\u001b[0;34m]\u001b[0m\u001b[0;34m,\u001b[0m \u001b[0mbatch_size\u001b[0m \u001b[0;34m=\u001b[0m \u001b[0;36m5\u001b[0m\u001b[0;34m,\u001b[0m \u001b[0mepochs\u001b[0m \u001b[0;34m=\u001b[0m \u001b[0;36m5\u001b[0m\u001b[0;34m)\u001b[0m\u001b[0;34m\u001b[0m\u001b[0;34m\u001b[0m\u001b[0m\n\u001b[0m",
      "\u001b[0;31mNameError\u001b[0m: name 'cnn_model' is not defined"
     ]
    }
   ],
   "source": [
    "history = cnn_model.fit(trnx_reshape, trny, validation_data = [tstx_reshape, tsty], batch_size = 5, epochs = 5)"
   ]
  },
  {
   "cell_type": "code",
   "execution_count": null,
   "id": "c4a5579b",
   "metadata": {},
   "outputs": [
    {
     "name": "stderr",
     "output_type": "stream",
     "text": [
      "ERROR:root:Internal Python error in the inspect module.\n",
      "Below is the traceback from this internal error.\n",
      "\n",
      "ERROR:root:Internal Python error in the inspect module.\n",
      "Below is the traceback from this internal error.\n",
      "\n",
      "ERROR:root:Internal Python error in the inspect module.\n",
      "Below is the traceback from this internal error.\n",
      "\n"
     ]
    },
    {
     "name": "stdout",
     "output_type": "stream",
     "text": [
      "Traceback (most recent call last):\n",
      "  File \"/home/questionnote/miniconda3/envs/tensorflow/lib/python3.7/site-packages/IPython/core/interactiveshell.py\", line 3524, in run_code\n",
      "    exec(code_obj, self.user_global_ns, self.user_ns)\n",
      "  File \"/tmp/ipykernel_7787/350508954.py\", line 1, in <module>\n",
      "    plt.plot(history.history['accuracy'])\n",
      "NameError: name 'history' is not defined\n",
      "\n",
      "During handling of the above exception, another exception occurred:\n",
      "\n",
      "Traceback (most recent call last):\n",
      "  File \"/home/questionnote/miniconda3/envs/tensorflow/lib/python3.7/site-packages/IPython/core/interactiveshell.py\", line 2088, in showtraceback\n",
      "    stb = value._render_traceback_()\n",
      "AttributeError: 'NameError' object has no attribute '_render_traceback_'\n",
      "\n",
      "During handling of the above exception, another exception occurred:\n",
      "\n",
      "Traceback (most recent call last):\n",
      "  File \"/home/questionnote/miniconda3/envs/tensorflow/lib/python3.7/site-packages/IPython/core/ultratb.py\", line 1101, in get_records\n",
      "    return _fixed_getinnerframes(etb, number_of_lines_of_context, tb_offset)\n",
      "  File \"/home/questionnote/miniconda3/envs/tensorflow/lib/python3.7/site-packages/IPython/core/ultratb.py\", line 248, in wrapped\n",
      "    return f(*args, **kwargs)\n",
      "  File \"/home/questionnote/miniconda3/envs/tensorflow/lib/python3.7/site-packages/IPython/core/ultratb.py\", line 281, in _fixed_getinnerframes\n",
      "    records = fix_frame_records_filenames(inspect.getinnerframes(etb, context))\n",
      "  File \"/home/questionnote/miniconda3/envs/tensorflow/lib/python3.7/inspect.py\", line 1502, in getinnerframes\n",
      "    frameinfo = (tb.tb_frame,) + getframeinfo(tb, context)\n",
      "  File \"/home/questionnote/miniconda3/envs/tensorflow/lib/python3.7/inspect.py\", line 1460, in getframeinfo\n",
      "    filename = getsourcefile(frame) or getfile(frame)\n",
      "  File \"/home/questionnote/miniconda3/envs/tensorflow/lib/python3.7/inspect.py\", line 696, in getsourcefile\n",
      "    if getattr(getmodule(object, filename), '__loader__', None) is not None:\n",
      "  File \"/home/questionnote/miniconda3/envs/tensorflow/lib/python3.7/inspect.py\", line 733, in getmodule\n",
      "    if ismodule(module) and hasattr(module, '__file__'):\n",
      "  File \"/home/questionnote/miniconda3/envs/tensorflow/lib/python3.7/site-packages/tensorflow/__init__.py\", line 50, in __getattr__\n",
      "    module = self._load()\n",
      "  File \"/home/questionnote/miniconda3/envs/tensorflow/lib/python3.7/site-packages/tensorflow/__init__.py\", line 44, in _load\n",
      "    module = _importlib.import_module(self.__name__)\n",
      "  File \"/home/questionnote/miniconda3/envs/tensorflow/lib/python3.7/importlib/__init__.py\", line 127, in import_module\n",
      "    return _bootstrap._gcd_import(name[level:], package, level)\n",
      "  File \"<frozen importlib._bootstrap>\", line 1006, in _gcd_import\n",
      "  File \"<frozen importlib._bootstrap>\", line 983, in _find_and_load\n",
      "  File \"<frozen importlib._bootstrap>\", line 965, in _find_and_load_unlocked\n",
      "ModuleNotFoundError: No module named 'tensorflow_core.estimator'\n",
      "Traceback (most recent call last):\n",
      "  File \"/home/questionnote/miniconda3/envs/tensorflow/lib/python3.7/site-packages/IPython/core/interactiveshell.py\", line 3524, in run_code\n",
      "    exec(code_obj, self.user_global_ns, self.user_ns)\n",
      "  File \"/tmp/ipykernel_7787/350508954.py\", line 1, in <module>\n",
      "    plt.plot(history.history['accuracy'])\n",
      "NameError: name 'history' is not defined\n",
      "\n",
      "During handling of the above exception, another exception occurred:\n",
      "\n",
      "Traceback (most recent call last):\n",
      "  File \"/home/questionnote/miniconda3/envs/tensorflow/lib/python3.7/site-packages/IPython/core/interactiveshell.py\", line 2088, in showtraceback\n",
      "    stb = value._render_traceback_()\n",
      "AttributeError: 'NameError' object has no attribute '_render_traceback_'\n",
      "\n",
      "During handling of the above exception, another exception occurred:\n",
      "\n",
      "Traceback (most recent call last):\n",
      "  File \"/home/questionnote/miniconda3/envs/tensorflow/lib/python3.7/site-packages/IPython/core/interactiveshell.py\", line 3444, in run_ast_nodes\n",
      "    if (await self.run_code(code, result,  async_=asy)):\n",
      "  File \"/home/questionnote/miniconda3/envs/tensorflow/lib/python3.7/site-packages/IPython/core/interactiveshell.py\", line 3541, in run_code\n",
      "    self.showtraceback(running_compiled_code=True)\n",
      "  File \"/home/questionnote/miniconda3/envs/tensorflow/lib/python3.7/site-packages/IPython/core/interactiveshell.py\", line 2091, in showtraceback\n",
      "    value, tb, tb_offset=tb_offset)\n",
      "  File \"/home/questionnote/miniconda3/envs/tensorflow/lib/python3.7/site-packages/IPython/core/ultratb.py\", line 1368, in structured_traceback\n",
      "    self, etype, value, tb, tb_offset, number_of_lines_of_context)\n",
      "  File \"/home/questionnote/miniconda3/envs/tensorflow/lib/python3.7/site-packages/IPython/core/ultratb.py\", line 1268, in structured_traceback\n",
      "    self, etype, value, tb, tb_offset, number_of_lines_of_context\n",
      "  File \"/home/questionnote/miniconda3/envs/tensorflow/lib/python3.7/site-packages/IPython/core/ultratb.py\", line 1125, in structured_traceback\n",
      "    tb_offset)\n",
      "  File \"/home/questionnote/miniconda3/envs/tensorflow/lib/python3.7/site-packages/IPython/core/ultratb.py\", line 1082, in format_exception_as_a_whole\n",
      "    last_unique, recursion_repeat = find_recursion(orig_etype, evalue, records)\n",
      "  File \"/home/questionnote/miniconda3/envs/tensorflow/lib/python3.7/site-packages/IPython/core/ultratb.py\", line 382, in find_recursion\n",
      "    return len(records), 0\n",
      "TypeError: object of type 'NoneType' has no len()\n",
      "\n",
      "During handling of the above exception, another exception occurred:\n",
      "\n",
      "Traceback (most recent call last):\n",
      "  File \"/home/questionnote/miniconda3/envs/tensorflow/lib/python3.7/site-packages/IPython/core/interactiveshell.py\", line 2088, in showtraceback\n",
      "    stb = value._render_traceback_()\n",
      "AttributeError: 'TypeError' object has no attribute '_render_traceback_'\n",
      "\n",
      "During handling of the above exception, another exception occurred:\n",
      "\n",
      "Traceback (most recent call last):\n",
      "  File \"/home/questionnote/miniconda3/envs/tensorflow/lib/python3.7/site-packages/IPython/core/ultratb.py\", line 1101, in get_records\n",
      "    return _fixed_getinnerframes(etb, number_of_lines_of_context, tb_offset)\n",
      "  File \"/home/questionnote/miniconda3/envs/tensorflow/lib/python3.7/site-packages/IPython/core/ultratb.py\", line 248, in wrapped\n",
      "    return f(*args, **kwargs)\n",
      "  File \"/home/questionnote/miniconda3/envs/tensorflow/lib/python3.7/site-packages/IPython/core/ultratb.py\", line 281, in _fixed_getinnerframes\n",
      "    records = fix_frame_records_filenames(inspect.getinnerframes(etb, context))\n",
      "  File \"/home/questionnote/miniconda3/envs/tensorflow/lib/python3.7/inspect.py\", line 1502, in getinnerframes\n",
      "    frameinfo = (tb.tb_frame,) + getframeinfo(tb, context)\n",
      "  File \"/home/questionnote/miniconda3/envs/tensorflow/lib/python3.7/inspect.py\", line 1460, in getframeinfo\n",
      "    filename = getsourcefile(frame) or getfile(frame)\n",
      "  File \"/home/questionnote/miniconda3/envs/tensorflow/lib/python3.7/inspect.py\", line 696, in getsourcefile\n",
      "    if getattr(getmodule(object, filename), '__loader__', None) is not None:\n",
      "  File \"/home/questionnote/miniconda3/envs/tensorflow/lib/python3.7/inspect.py\", line 733, in getmodule\n",
      "    if ismodule(module) and hasattr(module, '__file__'):\n",
      "  File \"/home/questionnote/miniconda3/envs/tensorflow/lib/python3.7/site-packages/tensorflow/__init__.py\", line 50, in __getattr__\n",
      "    module = self._load()\n",
      "  File \"/home/questionnote/miniconda3/envs/tensorflow/lib/python3.7/site-packages/tensorflow/__init__.py\", line 44, in _load\n",
      "    module = _importlib.import_module(self.__name__)\n",
      "  File \"/home/questionnote/miniconda3/envs/tensorflow/lib/python3.7/importlib/__init__.py\", line 127, in import_module\n",
      "    return _bootstrap._gcd_import(name[level:], package, level)\n",
      "  File \"<frozen importlib._bootstrap>\", line 1006, in _gcd_import\n",
      "  File \"<frozen importlib._bootstrap>\", line 983, in _find_and_load\n",
      "  File \"<frozen importlib._bootstrap>\", line 965, in _find_and_load_unlocked\n",
      "ModuleNotFoundError: No module named 'tensorflow_core.estimator'\n",
      "ERROR! Session/line number was not unique in database. History logging moved to new session 132\n",
      "Traceback (most recent call last):\n",
      "  File \"/home/questionnote/miniconda3/envs/tensorflow/lib/python3.7/site-packages/IPython/core/interactiveshell.py\", line 3524, in run_code\n",
      "    exec(code_obj, self.user_global_ns, self.user_ns)\n",
      "  File \"/tmp/ipykernel_7787/350508954.py\", line 1, in <module>\n",
      "    plt.plot(history.history['accuracy'])\n",
      "NameError: name 'history' is not defined\n",
      "\n",
      "During handling of the above exception, another exception occurred:\n",
      "\n",
      "Traceback (most recent call last):\n",
      "  File \"/home/questionnote/miniconda3/envs/tensorflow/lib/python3.7/site-packages/IPython/core/interactiveshell.py\", line 2088, in showtraceback\n",
      "    stb = value._render_traceback_()\n",
      "AttributeError: 'NameError' object has no attribute '_render_traceback_'\n",
      "\n",
      "During handling of the above exception, another exception occurred:\n",
      "\n",
      "Traceback (most recent call last):\n",
      "  File \"/home/questionnote/miniconda3/envs/tensorflow/lib/python3.7/site-packages/IPython/core/interactiveshell.py\", line 3444, in run_ast_nodes\n",
      "    if (await self.run_code(code, result,  async_=asy)):\n",
      "  File \"/home/questionnote/miniconda3/envs/tensorflow/lib/python3.7/site-packages/IPython/core/interactiveshell.py\", line 3541, in run_code\n",
      "    self.showtraceback(running_compiled_code=True)\n",
      "  File \"/home/questionnote/miniconda3/envs/tensorflow/lib/python3.7/site-packages/IPython/core/interactiveshell.py\", line 2091, in showtraceback\n",
      "    value, tb, tb_offset=tb_offset)\n",
      "  File \"/home/questionnote/miniconda3/envs/tensorflow/lib/python3.7/site-packages/IPython/core/ultratb.py\", line 1368, in structured_traceback\n",
      "    self, etype, value, tb, tb_offset, number_of_lines_of_context)\n",
      "  File \"/home/questionnote/miniconda3/envs/tensorflow/lib/python3.7/site-packages/IPython/core/ultratb.py\", line 1268, in structured_traceback\n",
      "    self, etype, value, tb, tb_offset, number_of_lines_of_context\n",
      "  File \"/home/questionnote/miniconda3/envs/tensorflow/lib/python3.7/site-packages/IPython/core/ultratb.py\", line 1125, in structured_traceback\n",
      "    tb_offset)\n",
      "  File \"/home/questionnote/miniconda3/envs/tensorflow/lib/python3.7/site-packages/IPython/core/ultratb.py\", line 1082, in format_exception_as_a_whole\n",
      "    last_unique, recursion_repeat = find_recursion(orig_etype, evalue, records)\n",
      "  File \"/home/questionnote/miniconda3/envs/tensorflow/lib/python3.7/site-packages/IPython/core/ultratb.py\", line 382, in find_recursion\n",
      "    return len(records), 0\n",
      "TypeError: object of type 'NoneType' has no len()\n",
      "\n",
      "During handling of the above exception, another exception occurred:\n",
      "\n",
      "Traceback (most recent call last):\n",
      "  File \"/home/questionnote/miniconda3/envs/tensorflow/lib/python3.7/site-packages/IPython/core/interactiveshell.py\", line 2088, in showtraceback\n",
      "    stb = value._render_traceback_()\n",
      "AttributeError: 'TypeError' object has no attribute '_render_traceback_'\n",
      "\n",
      "During handling of the above exception, another exception occurred:\n",
      "\n",
      "Traceback (most recent call last):\n",
      "  File \"/home/questionnote/miniconda3/envs/tensorflow/lib/python3.7/site-packages/IPython/core/interactiveshell.py\", line 3003, in _run_cell\n",
      "    return runner(coro)\n",
      "  File \"/home/questionnote/miniconda3/envs/tensorflow/lib/python3.7/site-packages/IPython/core/async_helpers.py\", line 78, in _pseudo_sync_runner\n",
      "    coro.send(None)\n",
      "  File \"/home/questionnote/miniconda3/envs/tensorflow/lib/python3.7/site-packages/IPython/core/interactiveshell.py\", line 3229, in run_cell_async\n",
      "    interactivity=interactivity, compiler=compiler, result=result)\n",
      "  File \"/home/questionnote/miniconda3/envs/tensorflow/lib/python3.7/site-packages/IPython/core/interactiveshell.py\", line 3463, in run_ast_nodes\n",
      "    self.showtraceback()\n",
      "  File \"/home/questionnote/miniconda3/envs/tensorflow/lib/python3.7/site-packages/IPython/core/interactiveshell.py\", line 2091, in showtraceback\n",
      "    value, tb, tb_offset=tb_offset)\n",
      "  File \"/home/questionnote/miniconda3/envs/tensorflow/lib/python3.7/site-packages/IPython/core/ultratb.py\", line 1368, in structured_traceback\n",
      "    self, etype, value, tb, tb_offset, number_of_lines_of_context)\n",
      "  File \"/home/questionnote/miniconda3/envs/tensorflow/lib/python3.7/site-packages/IPython/core/ultratb.py\", line 1268, in structured_traceback\n",
      "    self, etype, value, tb, tb_offset, number_of_lines_of_context\n",
      "  File \"/home/questionnote/miniconda3/envs/tensorflow/lib/python3.7/site-packages/IPython/core/ultratb.py\", line 1143, in structured_traceback\n",
      "    chained_exceptions_tb_offset)\n",
      "  File \"/home/questionnote/miniconda3/envs/tensorflow/lib/python3.7/site-packages/IPython/core/ultratb.py\", line 1082, in format_exception_as_a_whole\n",
      "    last_unique, recursion_repeat = find_recursion(orig_etype, evalue, records)\n",
      "  File \"/home/questionnote/miniconda3/envs/tensorflow/lib/python3.7/site-packages/IPython/core/ultratb.py\", line 382, in find_recursion\n",
      "    return len(records), 0\n",
      "TypeError: object of type 'NoneType' has no len()\n",
      "\n",
      "During handling of the above exception, another exception occurred:\n",
      "\n",
      "Traceback (most recent call last):\n",
      "  File \"/home/questionnote/miniconda3/envs/tensorflow/lib/python3.7/site-packages/IPython/core/interactiveshell.py\", line 2088, in showtraceback\n",
      "    stb = value._render_traceback_()\n",
      "AttributeError: 'TypeError' object has no attribute '_render_traceback_'\n",
      "\n",
      "During handling of the above exception, another exception occurred:\n",
      "\n",
      "Traceback (most recent call last):\n",
      "  File \"/home/questionnote/miniconda3/envs/tensorflow/lib/python3.7/site-packages/IPython/core/ultratb.py\", line 1101, in get_records\n",
      "    return _fixed_getinnerframes(etb, number_of_lines_of_context, tb_offset)\n",
      "  File \"/home/questionnote/miniconda3/envs/tensorflow/lib/python3.7/site-packages/IPython/core/ultratb.py\", line 248, in wrapped\n",
      "    return f(*args, **kwargs)\n",
      "  File \"/home/questionnote/miniconda3/envs/tensorflow/lib/python3.7/site-packages/IPython/core/ultratb.py\", line 281, in _fixed_getinnerframes\n",
      "    records = fix_frame_records_filenames(inspect.getinnerframes(etb, context))\n",
      "  File \"/home/questionnote/miniconda3/envs/tensorflow/lib/python3.7/inspect.py\", line 1502, in getinnerframes\n",
      "    frameinfo = (tb.tb_frame,) + getframeinfo(tb, context)\n",
      "  File \"/home/questionnote/miniconda3/envs/tensorflow/lib/python3.7/inspect.py\", line 1460, in getframeinfo\n",
      "    filename = getsourcefile(frame) or getfile(frame)\n",
      "  File \"/home/questionnote/miniconda3/envs/tensorflow/lib/python3.7/inspect.py\", line 696, in getsourcefile\n",
      "    if getattr(getmodule(object, filename), '__loader__', None) is not None:\n",
      "  File \"/home/questionnote/miniconda3/envs/tensorflow/lib/python3.7/inspect.py\", line 733, in getmodule\n",
      "    if ismodule(module) and hasattr(module, '__file__'):\n",
      "  File \"/home/questionnote/miniconda3/envs/tensorflow/lib/python3.7/site-packages/tensorflow/__init__.py\", line 50, in __getattr__\n",
      "    module = self._load()\n",
      "  File \"/home/questionnote/miniconda3/envs/tensorflow/lib/python3.7/site-packages/tensorflow/__init__.py\", line 44, in _load\n",
      "    module = _importlib.import_module(self.__name__)\n",
      "  File \"/home/questionnote/miniconda3/envs/tensorflow/lib/python3.7/importlib/__init__.py\", line 127, in import_module\n",
      "    return _bootstrap._gcd_import(name[level:], package, level)\n",
      "  File \"<frozen importlib._bootstrap>\", line 1006, in _gcd_import\n",
      "  File \"<frozen importlib._bootstrap>\", line 983, in _find_and_load\n",
      "  File \"<frozen importlib._bootstrap>\", line 965, in _find_and_load_unlocked\n",
      "ModuleNotFoundError: No module named 'tensorflow_core.estimator'\n"
     ]
    }
   ],
   "source": [
    "plt.plot(history.history['accuracy'])\n",
    "plt.plot(history.history['val_accuracy'])\n",
    "plt.title('model accuracy')\n",
    "plt.ylabel('accuracy')\n",
    "plt.xlabel('epoch')\n",
    "plt.legend(['train', 'test'], loc='upper left')\n",
    "plt.show()\n",
    "\n",
    "plt.plot(history.history['loss'])\n",
    "plt.plot(history.history['val_loss'])\n",
    "plt.title('model loss')\n",
    "plt.ylabel('loss')\n",
    "plt.xlabel('epoch')\n",
    "plt.legend(['train', 'test'], loc='upper left')\n",
    "plt.show()\n",
    "\n",
    "print(history.history['val_accuracy'][-1])\n",
    "print(np.max(history.history['val_accuracy']))"
   ]
  }
 ],
 "metadata": {
  "kernelspec": {
   "display_name": "Python 3 (ipykernel)",
   "language": "python",
   "name": "python3"
  },
  "language_info": {
   "codemirror_mode": {
    "name": "ipython",
    "version": 3
   },
   "file_extension": ".py",
   "mimetype": "text/x-python",
   "name": "python",
   "nbconvert_exporter": "python",
   "pygments_lexer": "ipython3",
   "version": "3.7.12"
  }
 },
 "nbformat": 4,
 "nbformat_minor": 5
}
